Workbook

Sheet MEMBERS
C1: HERITAGE CLUB
C3: MEMBERS INFORMATION DATA BASE
A4: S.n | B4: MBR Number | C4: Name | D4: Email Address | E4: Contact Number | F4: Address
A5: 1 | B5: HCFM-AH001 | C5: ADMIRAL AHMED HAYAT | D5: ahmadhayat.btic@gmail.com
A6: 2 | B6: HCFM-0502 | C6: MR. JABIR SHAHZAD | D6: Jabirshah@hotmil.com | E6: 03452430072 | F6: Appt# 76, Tower 04, Precinct-19, Bahria Town Karachi
A7: 3 | B7: HCFM-0503 | C7: MR.GHULAM NABI OTHI | D7: Alirazaothi@gmail.com | E7: 03002237405 | F7: Villa # 689, Street# 11, Iqbal Villa, Preccinct-02, Bahria Town Karachi
A8: 4 | B8: HCFM-0504 | C8: MR.BILAL AHMED | D8: bilalak061@gmail.com | E8: 03468214340 | F8: Quaid Villa# 118, Street# 03, Precinct-02, Bahria Town Karachi
A9: 5 | B9: HCFM-0506 | C9: MR.MUHAMMAD ARIF | D9: maszone1980@gmail.com | E9: 03212669061 | F9: Appt#114, Tower 22, Precinct-19, Bahria Town Karachi
A10: 6 | B10: HCFM-0507 | C10: MR.SYED TAHIR ABBAS | D10: Syed.tahir.abbas@hotmail.com | E10: 03218202201 | F10: Villa# 2509, Street # 60, Precinct- 27, Bahria Town Karachi
A11: 7 | B11: HCFM-0508 | C11: MR.SHIRAZ AHMED | D11: sh-ahmed@hotmail.com | E11: 03452362138 | F11: Apt# 107, 4th Floor , Tower 11, Precinct -19, Bahria Town Karachi
A12: 8 | B12: HCFM-0509 | C12: MR.SYED ABDULLAH ALI | D12: Syedabdullchali89@gmil.com | E12: 03339049974 | F12: Villa# 7546, Street# 23, Road-01, Precinct-16, Bahria Town Karachi
A13: 9 | B13: HCFM-0510 | C13: MR.MUHAMMAD RIZWAN | D13: meshgroup193@gmail.com | E13: 03212245690 | F13: Villa# 536, Street# 15, Road-07, Precinct-04, Bahria Town Karachi
A14: 10 | B14: HCFM-0511 | C14: MR.TALHAR AHMED | D14: Talharshaikh4@gmail.com | E14: 03333653690 | F14: Appt# 104, 4th Floor, TOWER-11, Precinct-19, Bahria Town Karachi
A15: 11 | B15: HCFM-0512 | C15: MR.ZEESHAN IQBAL | D15: zchamdia@gmail.com | E15: 03222409333 | F15: Appt # 113, Tower 04, Precinct-19, Bahria Town Karachi
A16: 12 | B16: HCFM-0513 | C16: MR.SAJJAD ALI | D16: Sajjad.Kazi.isra@gmail.com | E16: 03003012497 | F16: Villa# 06, Road-01, Precinct-04, Bahria Town Karachi
A17: 13 | B17: HCFM-0514 | C17: MR.DILEEP KUMAR | D17: dgomani@yahoo.com | E17: 03332655987 | F17: House# A-50, Palm Enclave Housing Society, Bypass Hyderabad
A18: 14 | B18: HCFM-0515 | C18: MR.TARIQUE ZUBAIR | D18: tariq.zubair@btkarachi.com | E18: 03003895969
A19: 15 | B19: HCFM-0516 | C19: MR.ATIF SHAFQAT | D19: Shafqatatif@hotmail.com | E19: 03364407555 | F19: Quaid Villa# 184, Street# 05, Precinct-02, Bahria Town Karchi
A20: 16 | B20: HCFM-0517 | C20: DR.ATHESHAM UL HAQ RANA | D20: ahaqrana111@icloud.com | E20: 03009318597 | F20: Villa# 728, Street # 11, Road-4, Precinct-10A, Bahria Town Karachi
A21: 17 | B21: HCFM-0518 | C21: DR.SANTOSH KUMAR | D21: drsantoshpamnani@gmail.com | E21: 03212014843 | F21: Appt # 91, Tower 22, Precinct- 19, Bahria Town Karachi
A22: 18 | B22: HCFM-0519 | C22: DR.NAZEER HUSSAIN KALHORO | D22: drnazeerhussain@hotmail.com | E22: 03114605474 | F22: Villa# 756, Street 23 , Precinct- 01, Bahria Town Karachi
A23: 19 | B23: HCFM-0520 | C23: MR.NIZAM UDDIN NIZAMANI | D23: nizambaloch@gmail.com | E23: 03452220862 | F23: Villa # 211, Street # 01, Precinct-11-A, Bahria Town Karachi
A24: 20 | B24: HCFM-0521 | C24: MR.HAFEEZ AHMED SIYAL | D24: hafeezsiyal09@gmail.com | E24: 03008379253 | F24: Villa#1990, Road-15, Precinct-12, Ali Block, Bahria Town Karchi
A25: 21 | B25: HCFM-0522 | C25: MR.IQBAL AHMED MALLAH | D25: Iqbalahmed.Mallah@hotmail.com | E25: 03009249097 | F25: Villa#1642, Loop Road, Precinct 10-A, Bahria Town Karachi.
A26: 22 | B26: HCFM-0523 | C26: MR.KANYO LAL | D26: Kanyolal.Mandhwani@gmail.com | E26: 03335414613 | F26: Pent House # 02, 5th Floor Mustafa Arcade, SMCH- Block-A Karachi
A27: 23 | B27: HCFM-0524 | C27: MR.MANOJ KUMAR | D27: Mkvedani@gmil.com | E27: 03332881142 | F27: Appt # 96, Tower 08, Precinct - 19, Bahria Town Karachi
A28: 24 | B28: HCFM-0525 | C28: DR.SAJJAD AHMED SOLANGI | D28: Solangisajjad1977@gmail.com | E28: 03272102384 | F28: Villa # 230, Street # 03, Precinct - 10-A, Bahria Town Karachi
A29: 25 | B29: HCFM-0526 | C29: MR.MUIED AHMED DURRANI | D29: Muied@outlook.com | E29: 03462885409 | F29: Villa # 1012 , Street # 13 , Precinct-31 , Bahria Town Karachi
A30: 26 | B30: HCFM-0527 | C30: MR.SAEED AHMED | D30: Sanoorhafsa123@gmail.com | E30: 03212112153 | F30: Villa # 05, Street # 31, Precinct-35, Sportcity, Bahria Town Karachi
... A32: 28 | B32: HCFM-0529 | C32: DR.UMER QAZI | D32: docuk1982@yahoo.com | E32: 03361853609 | F32: Villa# 06, Road-01, Precinct-04, Bahria Town Karachi
A33: 29 | B33: HCFM-0530 | C33: MR.MUHAMMAD HANIF | D33: haneef_pk@hotmail.com | E33: 3002021430 | F33: Villa# 105, Loop Road, Precinct-06, Bahria Town Karachi
A34: 30 | B34: HCFM-0532 | C34: MR.KHALID JAVED | D34: khalid.javed@omsltd.net | E34: 03458437686 | F34: Villa# 1575, Street # 23, Precinct-08, Bahria Town Karachi
A35: 31 | B35: HCFM-0533 | C35: MR.ZULQARNAIN | D35: zulqarnainhabib@gmail.com | E35: 3332110598 | F35: Villa # 594, Street # 19, Precinct # 01, Bahria Town Karachi
A36: 32 | B36: HCFM-0534 | C36: MR.PIR MUJEEB JAN SARHANDI | D36: hamzajan1996@hotmail.com | E36: 03003029453 | F36: Appt # 118, 5th Floor, Tower# 15, Bahria Town Karachi
A37: 33 | B37: HCFM-0535 | C37: MR.MUHAMMAD ASIF | D37: hammadasif801@gmail.com | E37: 03002901230 | F37: Villa# 164, Precinct # 02, Quaid Block, Bahria Town Karachi
A38: 34 | B38: HCFM-0536 | C38: MR.ASHOK KUMAR | D38: arta_ashoka@hotmail.com | E38: 03332638079 | F38: Quaid Villa # 141, Street # 4, Precinct # 02, Bahria Town Karachi
A39: 35 | B39: HCFM-0538 | C39: MR.MUHAMMAD ZAIN | D39: zuraaco_z@gmail.com | E39: 03212106668 | F39: Villa# 0236, Street 06, Precinct #02, Quaid Block, Bahria Town Karachi
A40: 36 | B40: HCFM-0539 | C40: MR.QAMARUZZAMAN | D40: Qamar@ezzaintl.com | E40: 03008269322 | F40: A2 3/30 Flat C4 , 3rd Floor , Nazimabad # 2 , Awan-e-Hashim , Karachi
A41: 37 | B41: HCFM-0540 | C41: MR.MUHAMMAD SALIQ SIDDIQUI | D41: ssiddiqi2@yahoo.com | E41: 030021333997 | F41: Dolmen Arcade, Block 3 , B.Y.J.C.H.S, Appt #609, Bahadurabad, Karachi
A42: 38 | B42: HCFM-0541 | C42: MR.SHAN ELAHI SEHGAL | D42: Shanelahisehgal@hotmail.com | E42: 03367890911 | F42: Villa# 1567, Precinct #10-A, Bahria Town Karachi
...

Sheet data base 
A1: S.NO | B1: MBR ID | C1: MBR NAME | D1: BOWLING ALLEY | E1: GYM | F1: FAMILY POOL | G1: SQUASH COURT | H1: LADIES POOL | I1: CHILDERN PLAY AREA | J1: CINEMA | K1: Cigar Lounge | L1: Pool Lockers | M1: SPA | N1: Padel Court | O1: Ladies Saloon | P1: HC Chambers | Q1: Gym Sub | R1: PARTY | S1: VANU CHARGES | T1: FOOD & BEVERAGES | U1: (SST) | V1: MONTHLY SUBSCRIPTION | W1: TOTAL | X1: AREARS | Y1: ADVANCED | Z1: MANDATORY CHARGES | AA1: TOTAL BILLED AMOUNT | AB1: LATE PAYMENT SURCHARGE | AC1: DUE DATE | AD1: AMOUNT AFTER DUE DATE
A2: 1 | B2: HCFM-AH001 | C2: ADMIRAL AHMED HAYAT | D2: =SUMIFS(FACILITIES!E:E,FACILITIES!$B:$B,B2) -> 0 | E2: =SUMIFS(FACILITIES!F:F,FACILITIES!$B:$B,$B2) -> 0 | F2: =SUMIFS(FACILITIES!G:G,FACILITIES!$B:$B,B2) -> 0 | G2: =SUMIFS(FACILITIES!H:H,FACILITIES!$B:$B,B2) -> 0 | H2: =SUMIFS(FACILITIES!I:I,FACILITIES!$B:$B,B2) -> 0 | I2: =SUMIFS(FACILITIES!J:J,FACILITIES!$B:$B,B2) -> 0 | J2: =SUMIFS(FACILITIES!K:K,FACILITIES!$B:$B,B2) -> 0 | K2: =SUMIFS(FACILITIES!L:L,FACILITIES!$B:$B,B2) -> 0 | L2: =SUMIFS(FACILITIES!M:M,FACILITIES!$B:$B,B2) -> 0 | M2: =SUMIFS(FACILITIES!N:N,FACILITIES!$B:$B,B2) -> 0 | N2: =SUMIFS(FACILITIES!O:O,FACILITIES!$B:$B,B2) -> 0 | O2: =SUMIFS(FACILITIES!P:P,FACILITIES!$B:$B,B2) -> 0 | P2: =SUMIFS(FACILITIES!Q:Q,FACILITIES!$B:$B,B2) -> 0 | Q2: =SUMIFS(FACILITIES!R:R,FACILITIES!$B:$B,B2) -> 0 | R2: =SUMIFS(FACILITIES!T:T,FACILITIES!B:B,B2) -> 0 | S2: =SUMIFS(FACILITIES!S:S,FACILITIES!B:B,B2) -> 0 | T2: =SUMIFS('F & B'!G:G,'F & B'!B:B,B2) -> 24550 | U2: =T2*0.15 -> 3682.5 | V2: =SUMIFS('FIXED AMOUNT'!G:G,'FIXED AMOUNT'!B:B,B2) -> 7000 | W2: =SUM(D2:V2) -> 35232.5 | X2: =SUMIFS('FIXED AMOUNT'!E:E,'FIXED AMOUNT'!B:B,'data base '!B:B) -> 0 | Y2: =SUMIFS('FIXED AMOUNT'!F:F,'FIXED AMOUNT'!B:B,'data base '!B:B) -> 0 | Z2: =SUMIFS('FIXED AMOUNT'!V:V,'FIXED AMOUNT'!B:B,B:B) -> 0 | AA2: =W2+X2-Y2+Z2 -> 35232.5 | AB2: =W2*0.1 -> 3523.25 | AC2: 45945 | AD2: =AA2+AB2 -> 38755.75
A3: 2 | B3: HCFM-0502 | C3: MR. JABIR SHAHZAD | D3: =SUMIFS(FACILITIES!E:E,FACILITIES!$B:$B,B3) -> 0 | E3: =SUMIFS(FACILITIES!F:F,FACILITIES!$B:$B,$B3) -> 750 | F3: =SUMIFS(FACILITIES!G:G,FACILITIES!$B:$B,B3) -> 0 | G3: =SUMIFS(FACILITIES!H:H,FACILITIES!$B:$B,B3) -> 0 | H3: =SUMIFS(FACILITIES!I:I,FACILITIES!$B:$B,B3) -> 0 | I3: =SUMIFS(FACILITIES!J:J,FACILITIES!$B:$B,B3) -> 1100 | J3: =SUMIFS(FACILITIES!K:K,FACILITIES!$B:$B,B3) -> 0 | K3: =SUMIFS(FACILITIES!L:L,FACILITIES!$B:$B,B3) -> 0 | L3: =SUMIFS(FACILITIES!M:M,FACILITIES!$B:$B,B3) -> 0 | M3: =SUMIFS(FACILITIES!N:N,FACILITIES!$B:$B,B3) -> 0 | N3: =SUMIFS(FACILITIES!O:O,FACILITIES!$B:$B,B3) -> 0 | O3: =SUMIFS(FACILITIES!P:P,FACILITIES!$B:$B,B3) -> 0 | P3: =SUMIFS(FACILITIES!Q:Q,FACILITIES!$B:$B,B3) -> 0 | Q3: =SUMIFS(FACILITIES!R:R,FACILITIES!$B:$B,B3) -> 0 | R3: =SUMIFS(FACILITIES!T:T,FACILITIES!B:B,B3) -> 0 | S3: =SUMIFS(FACILITIES!S:S,FACILITIES!B:B,B3) -> 0 | T3: =SUMIFS('F & B'!G:G,'F & B'!B:B,B3) -> 12950 | U3: =T3*0.15 -> 1942.5 | V3: =SUMIFS('FIXED AMOUNT'!G:G,'FIXED AMOUNT'!B:B,B3) -> 7000 | W3: =SUM(D3:V3) -> 23742.5 | X3: =SUMIFS('FIXED AMOUNT'!E:E,'FIXED AMOUNT'!B:B,'data base '!B:B) -> 0 | Y3: =SUMIFS('FIXED AMOUNT'!F:F,'FIXED AMOUNT'!B:B,'data base '!B:B) -> 0 | Z3: =SUMIFS('FIXED AMOUNT'!V:V,'FIXED AMOUNT'!B:B,B:B) -> 0 | AA3: =W3+X3-Y3+Z3 -> 23742.5 | AB3: =W3*0.1 -> 2374.25 | AC3: 45945 | AD3: =AA3+AB3 -> 26116.75
A4: 3 | B4: HCFM-0503 | C4: MR.GHULAM NABI OTHI | D4: =SUMIFS(FACILITIES!E:E,FACILITIES!$B:$B,B4) -> 0 | E4: =SUMIFS(FACILITIES!F:F,FACILITIES!$B:$B,$B4) -> 0 | F4: =SUMIFS(FACILITIES!G:G,FACILITIES!$B:$B,B4) -> 0 | G4: =SUMIFS(FACILITIES!H:H,FACILITIES!$B:$B,B4) -> 0 | H4: =SUMIFS(FACILITIES!I:I,FACILITIES!$B:$B,B4) -> 0 | I4: =SUMIFS(FACILITIES!J:J,FACILITIES!$B:$B,B4) -> 0 | J4: =SUMIFS(FACILITIES!K:K,FACILITIES!$B:$B,B4) -> 0 | K4: =SUMIFS(FACILITIES!L:L,FACILITIES!$B:$B,B4) -> 0 | L4: =SUMIFS(FACILITIES!M:M,FACILITIES!$B:$B,B4) -> 0 | M4: =SUMIFS(FACILITIES!N:N,FACILITIES!$B:$B,B4) -> 0 | N4: =SUMIFS(FACILITIES!O:O,FACILITIES!$B:$B,B4) -> 0 | O4: =SUMIFS(FACILITIES!P:P,FACILITIES!$B:$B,B4) -> 0 | P4: =SUMIFS(FACILITIES!Q:Q,FACILITIES!$B:$B,B4) -> 0 | Q4: =SUMIFS(FACILITIES!R:R,FACILITIES!$B:$B,B4) -> 0 | R4: =SUMIFS(FACILITIES!T:T,FACILITIES!B:B,B4) -> 0 | S4: =SUMIFS(FACILITIES!S:S,FACILITIES!B:B,B4) -> 5000 | T4: =SUMIFS('F & B'!G:G,'F & B'!B:B,B4) -> 52578 | U4: =T4*0.15 -> 7886.7 | V4: =SUMIFS('FIXED AMOUNT'!G:G,'FIXED AMOUNT'!B:B,B4) -> 7000 | W4: =SUM(D4:V4) -> 72464.7 | X4: =SUMIFS('FIXED AMOUNT'!E:E,'FIXED AMOUNT'!B:B,'data base '!B:B) -> 0 | Y4: =SUMIFS('FIXED AMOUNT'!F:F,'FIXED AMOUNT'!B:B,'data base '!B:B) -> 0 | Z4: =SUMIFS('FIXED AMOUNT'!V:V,'FIXED AMOUNT'!B:B,B:B) -> 0 | AA4: =W4+X4-Y4+Z4 -> 72464.7 | AB4: =W4*0.1 -> 7246.47 | AC4: 45945 | AD4: =AA4+AB4 -> 79711.17
A5: 4 | B5: HCFM-0504 | C5: MR.BILAL AHMED | D5: =SUMIFS(FACILITIES!E:E,FACILITIES!$B:$B,B5) -> 0 | E5: =SUMIFS(FACILITIES!F:F,FACILITIES!$B:$B,$B5) -> 0 | F5: =SUMIFS(FACILITIES!G:G,FACILITIES!$B:$B,B5) -> 0 | G5: =SUMIFS(FACILITIES!H:H,FACILITIES!$B:$B,B5) -> 0 | H5: =SUMIFS(FACILITIES!I:I,FACILITIES!$B:$B,B5) -> 0 | I5: =SUMIFS(FACILITIES!J:J,FACILITIES!$B:$B,B5) -> 500 | J5: =SUMIFS(FACILITIES!K:K,FACILITIES!$B:$B,B5) -> 0 | K5: =SUMIFS(FACILITIES!L:L,FACILITIES!$B:$B,B5) -> 0 | L5: =SUMIFS(FACILITIES!M:M,FACILITIES!$B:$B,B5) -> 0 | M5: =SUMIFS(FACILITIES!N:N,FACILITIES!$B:$B,B5) -> 0 | N5: =SUMIFS(FACILITIES!O:O,FACILITIES!$B:$B,B5) -> 0 | O5: =SUMIFS(FACILITIES!P:P,FACILITIES!$B:$B,B5) -> 0 | P5: =SUMIFS(FACILITIES!Q:Q,FACILITIES!$B:$B,B5) -> 0 | Q5: =SUMIFS(FACILITIES!R:R,FACILITIES!$B:$B,B5) -> 0 | R5: =SUMIFS(FACILITIES!T:T,FACILITIES!B:B,B5) -> 0 | S5: =SUMIFS(FACILITIES!S:S,FACILITIES!B:B,B5) -> 0 | T5: =SUMIFS('F & B'!G:G,'F & B'!B:B,B5) -> 6550 | U5: =T5*0.15 -> 982.5 | V5: =SUMIFS('FIXED AMOUNT'!G:G,'FIXED AMOUNT'!B:B,B5) -> 7000 | W5: =SUM(D5:V5) -> 15032.5 | X5: =SUMIFS('FIXED AMOUNT'!E:E,'FIXED AMOUNT'!B:B,'data base '!B:B) -> 0 | Y5: =SUMIFS('FIXED AMOUNT'!F:F,'FIXED AMOUNT'!B:B,'data base '!B:B) -> 0 | Z5: =SUMIFS('FIXED AMOUNT'!V:V,'FIXED AMOUNT'!B:B,B:B) -> 0 | AA5: =W5+X5-Y5+Z5 -> 15032.5 | AB5: =W5*0.1 -> 1503.25 | AC5: 45945 | AD5: =AA5+AB5 -> 16535.75
A6: 5 | B6: HCFM-0506 | C6: MR.MUHAMMAD ARIF | D6: =SUMIFS(FACILITIES!E:E,FACILITIES!$B:$B,B6) -> 2700 | E6: =SUMIFS(FACILITIES!F:F,FACILITIES!$B:$B,$B6) -> 0 | F6: =SUMIFS(FACILITIES!G:G,FACILITIES!$B:$B,B6) -> 0 | G6: =SUMIFS(FACILITIES!H:H,FACILITIES!$B:$B,B6) -> 0 | H6: =SUMIFS(FACILITIES!I:I,FACILITIES!$B:$B,B6) -> 0 | I6: =SUMIFS(FACILITIES!J:J,FACILITIES!$B:$B,B6) -> 600 | J6: =SUMIFS(FACILITIES!K:K,FACILITIES!$B:$B,B6) -> 0 | K6: =SUMIFS(FACILITIES!L:L,FACILITIES!$B:$B,B6) -> 0 | L6: =SUMIFS(FACILITIES!M:M,FACILITIES!$B:$B,B6) -> 0 | M6: =SUMIFS(FACILITIES!N:N,FACILITIES!$B:$B,B6) -> 0 | N6: =SUMIFS(FACILITIES!O:O,FACILITIES!$B:$B,B6) -> 0 | O6: =SUMIFS(FACILITIES!P:P,FACILITIES!$B:$B,B6) -> 0 | P6: =SUMIFS(FACILITIES!Q:Q,FACILITIES!$B:$B,B6) -> 0 | Q6: =SUMIFS(FACILITIES!R:R,FACILITIES!$B:$B,B6) -> 0 | R6: =SUMIFS(FACILITIES!T:T,FACILITIES!B:B,B6) -> 0 | S6: =SUMIFS(FACILITIES!S:S,FACILITIES!B:B,B6) -> 0 | T6: =SUMIFS('F & B'!G:G,'F & B'!B:B,B6) -> 22657 | U6: =T6*0.15 -> 3398.55 | V6: =SUMIFS('FIXED AMOUNT'!G:G,'FIXED AMOUNT'!B:B,B6) -> 7000 | W6: =SUM(D6:V6) -> 36355.55 | X6: =SUMIFS('FIXED AMOUNT'!E:E,'FIXED AMOUNT'!B:B,'data base '!B:B) -> 0 | Y6: =SUMIFS('FIXED AMOUNT'!F:F,'FIXED AMOUNT'!B:B,'data base '!B:B) -> 0 | Z6: =SUMIFS('FIXED AMOUNT'!V:V,'FIXED AMOUNT'!B:B,B:B) -> 8474 | AA6: =W6+X6-Y6+Z6 -> 44829.55 | AB6: =W6*0.1 -> 3635.555 | AC6: 45945 | AD6: =AA6+AB6 -> 48465.105
A7: 6 | B7: HCFM-0507 | C7: MR.SYED TAHIR ABBAS | D7: =SUMIFS(FACILITIES!E:E,FACILITIES!$B:$B,B7) -> 0 | E7: =SUMIFS(FACILITIES!F:F,FACILITIES!$B:$B,$B7) -> 0 | F7: =SUMIFS(FACILITIES!G:G,FACILITIES!$B:$B,B7) -> 0 | G7: =SUMIFS(FACILITIES!H:H,FACILITIES!$B:$B,B7) -> 0 | H7: =SUMIFS(FACILITIES!I:I,FACILITIES!$B:$B,B7) -> 0 | I7: =SUMIFS(FACILITIES!J:J,FACILITIES!$B:$B,B7) -> 0 | J7: =SUMIFS(FACILITIES!K:K,FACILITIES!$B:$B,B7) -> 0 | K7: =SUMIFS(FACILITIES!L:L,FACILITIES!$B:$B,B7) -> 0 | L7: =SUMIFS(FACILITIES!M:M,FACILITIES!$B:$B,B7) -> 0 | M7: =SUMIFS(FACILITIES!N:N,FACILITIES!$B:$B,B7) -> 0 | N7: =SUMIFS(FACILITIES!O:O,FACILITIES!$B:$B,B7) -> 0 | O7: =SUMIFS(FACILITIES!P:P,FACILITIES!$B:$B,B7) -> 0 | P7: =SUMIFS(FACILITIES!Q:Q,FACILITIES!$B:$B,B7) -> 0 | Q7: =SUMIFS(FACILITIES!R:R,FACILITIES!$B:$B,B7) -> 0 | R7: =SUMIFS(FACILITIES!T:T,FACILITIES!B:B,B7) -> 0 | S7: =SUMIFS(FACILITIES!S:S,FACILITIES!B:B,B7) -> 0 | T7: =SUMIFS('F & B'!G:G,'F & B'!B:B,B7) -> 3200 | U7: =T7*0.15 -> 480 | V7: =SUMIFS('FIXED AMOUNT'!G:G,'FIXED AMOUNT'!B:B,B7) -> 7000 | W7: =SUM(D7:V7) -> 10680 | X7: =SUMIFS('FIXED AMOUNT'!E:E,'FIXED AMOUNT'!B:B,'data base '!B:B) -> 0 | Y7: =SUMIFS('FIXED AMOUNT'!F:F,'FIXED AMOUNT'!B:B,'data base '!B:B) -> 0 | Z7: =SUMIFS('FIXED AMOUNT'!V:V,'FIXED AMOUNT'!B:B,B:B) -> 44350 | AA7: =W7+X7-Y7+Z7 -> 55030 | AB7: =W7*0.1 -> 1068 | AC7: 45945 | AD7: =AA7+AB7 -> 56098
A8: 7 | B8: HCFM-0508 | C8: MR.SHIRAZ AHMED | D8: =SUMIFS(FACILITIES!E:E,FACILITIES!$B:$B,B8) -> 2400 | E8: =SUMIFS(FACILITIES!F:F,FACILITIES!$B:$B,$B8) -> 0 | F8: =SUMIFS(FACILITIES!G:G,FACILITIES!$B:$B,B8) -> 0 | G8: =SUMIFS(FACILITIES!H:H,FACILITIES!$B:$B,B8) -> 0 | H8: =SUMIFS(FACILITIES!I:I,FACILITIES!$B:$B,B8) -> 0 | I8: =SUMIFS(FACILITIES!J:J,FACILITIES!$B:$B,B8) -> 1100 | J8: =SUMIFS(FACILITIES!K:K,FACILITIES!$B:$B,B8) -> 0 | K8: =SUMIFS(FACILITIES!L:L,FACILITIES!$B:$B,B8) -> 0 | L8: =SUMIFS(FACILITIES!M:M,FACILITIES!$B:$B,B8) -> 0 | M8: =SUMIFS(FACILITIES!N:N,FACILITIES!$B:$B,B8) -> 0 | N8: =SUMIFS(FACILITIES!O:O,FACILITIES!$B:$B,B8) -> 0 | O8: =SUMIFS(FACILITIES!P:P,FACILITIES!$B:$B,B8) -> 0 | P8: =SUMIFS(FACILITIES!Q:Q,FACILITIES!$B:$B,B8) -> 0 | Q8: =SUMIFS(FACILITIES!R:R,FACILITIES!$B:$B,B8) -> 0 | R8: =SUMIFS(FACILITIES!T:T,FACILITIES!B:B,B8) -> 0 | S8: =SUMIFS(FACILITIES!S:S,FACILITIES!B:B,B8) -> 0 | T8: =SUMIFS('F & B'!G:G,'F & B'!B:B,B8) -> 0 | U8: =T8*0.15 -> 0 | V8: =SUMIFS('FIXED AMOUNT'!G:G,'FIXED AMOUNT'!B:B,B8) -> 7000 | W8: =SUM(D8:V8) -> 10500 | X8: =SUMIFS('FIXED AMOUNT'!E:E,'FIXED AMOUNT'!B:B,'data base '!B:B) -> 0 | Y8: =SUMIFS('FIXED AMOUNT'!F:F,'FIXED AMOUNT'!B:B,'data base '!B:B) -> 0 | Z8: =SUMIFS('FIXED AMOUNT'!V:V,'FIXED AMOUNT'!B:B,B:B) -> 0 | AA8: =W8+X8-Y8+Z8 -> 10500 | AB8: =W8*0.1 -> 1050 | AC8: 45945 | AD8: =AA8+AB8 -> 11550
A9: 8 | B9: HCFM-0509 | C9: MR.SYED ABDULLAH ALI | D9: =SUMIFS(FACILITIES!E:E,FACILITIES!$B:$B,B9) -> 0 | E9: =SUMIFS(FACILITIES!F:F,FACILITIES!$B:$B,$B9) -> 600 | F9: =SUMIFS(FACILITIES!G:G,FACILITIES!$B:$B,B9) -> 0 | G9: =SUMIFS(FACILITIES!H:H,FACILITIES!$B:$B,B9) -> 0 | H9: =SUMIFS(FACILITIES!I:I,FACILITIES!$B:$B,B9) -> 0 | I9: =SUMIFS(FACILITIES!J:J,FACILITIES!$B:$B,B9) -> 0 | J9: =SUMIFS(FACILITIES!K:K,FACILITIES!$B:$B,B9) -> 0 | K9: =SUMIFS(FACILITIES!L:L,FACILITIES!$B:$B,B9) -> 0 | L9: =SUMIFS(FACILITIES!M:M,FACILITIES!$B:$B,B9) -> 0 | M9: =SUMIFS(FACILITIES!N:N,FACILITIES!$B:$B,B9) -> 0 | N9: =SUMIFS(FACILITIES!O:O,FACILITIES!$B:$B,B9) -> 0 | O9: =SUMIFS(FACILITIES!P:P,FACILITIES!$B:$B,B9) -> 0 | P9: =SUMIFS(FACILITIES!Q:Q,FACILITIES!$B:$B,B9) -> 0 | Q9: =SUMIFS(FACILITIES!R:R,FACILITIES!$B:$B,B9) -> 0 | R9: =SUMIFS(FACILITIES!T:T,FACILITIES!B:B,B9) -> 0 | S9: =SUMIFS(FACILITIES!S:S,FACILITIES!B:B,B9) -> 0 | T9: =SUMIFS('F & B'!G:G,'F & B'!B:B,B9) -> 1300 | U9: =T9*0.15 -> 195 | V9: =SUMIFS('FIXED AMOUNT'!G:G,'FIXED AMOUNT'!B:B,B9) -> 7000 | W9: =SUM(D9:V9) -> 9095 | X9: =SUMIFS('FIXED AMOUNT'!E:E,'FIXED AMOUNT'!B:B,'data base '!B:B) -> 0 | Y9: =SUMIFS('FIXED AMOUNT'!F:F,'FIXED AMOUNT'!B:B,'data base '!B:B) -> 0 | Z9: =SUMIFS('FIXED AMOUNT'!V:V,'FIXED AMOUNT'!B:B,B:B) -> 0 | AA9: =W9+X9-Y9+Z9 -> 9095 | AB9: =W9*0.1 -> 909.5 | AC9: 45945 | AD9: =AA9+AB9 -> 10004.5
A10: 9 | B10: HCFM-0510 | C10: MR.MUHAMMAD RIZWAN | D10: =SUMIFS(FACILITIES!E:E,FACILITIES!$B:$B,B10) -> 1800 | E10: =SUMIFS(FACILITIES!F:F,FACILITIES!$B:$B,$B10) -> 750 | F10: =SUMIFS(FACILITIES!G:G,FACILITIES!$B:$B,B10) -> 0 | G10: =SUMIFS(FACILITIES!H:H,FACILITIES!$B:$B,B10) -> 0 | H10: =SUMIFS(FACILITIES!I:I,FACILITIES!$B:$B,B10) -> 0 | I10: =SUMIFS(FACILITIES!J:J,FACILITIES!$B:$B,B10) -> 0 | J10: =SUMIFS(FACILITIES!K:K,FACILITIES!$B:$B,B10) -> 0 | K10: =SUMIFS(FACILITIES!L:L,FACILITIES!$B:$B,B10) -> 0 | L10: =SUMIFS(FACILITIES!M:M,FACILITIES!$B:$B,B10) -> 0 | M10: =SUMIFS(FACILITIES!N:N,FACILITIES!$B:$B,B10) -> 0 | N10: =SUMIFS(FACILITIES!O:O,FACILITIES!$B:$B,B10) -> 0 | O10: =SUMIFS(FACILITIES!P:P,FACILITIES!$B:$B,B10) -> 0 | P10: =SUMIFS(FACILITIES!Q:Q,FACILITIES!$B:$B,B10) -> 0 | Q10: =SUMIFS(FACILITIES!R:R,FACILITIES!$B:$B,B10) -> 0 | R10: =SUMIFS(FACILITIES!T:T,FACILITIES!B:B,B10) -> 0 | S10: =SUMIFS(FACILITIES!S:S,FACILITIES!B:B,B10) -> 0 | T10: =SUMIFS('F & B'!G:G,'F & B'!B:B,B10) -> 500 | U10: =T10*0.15 -> 75 | V10: =SUMIFS('FIXED AMOUNT'!G:G,'FIXED AMOUNT'!B:B,B10) -> 7000 | W10: =SUM(D10:V10) -> 10125 | X10: =SUMIFS('FIXED AMOUNT'!E:E,'FIXED AMOUNT'!B:B,'data base '!B:B) -> 0 | Y10: =SUMIFS('FIXED AMOUNT'!F:F,'FIXED AMOUNT'!B:B,'data base '!B:B) -> 0 | Z10: =SUMIFS('FIXED AMOUNT'!V:V,'FIXED AMOUNT'!B:B,B:B) -> 17926 | AA10: =W10+X10-Y10+Z10 -> 28051 | AB10: =W10*0.1 -> 1012.5 | AC10: 45945 | AD10: =AA10+AB10 -> 29063.5
A11: 10 | B11: HCFM-0511 | C11: MR.TALHAR AHMED | D11: =SUMIFS(FACILITIES!E:E,FACILITIES!$B:$B,B11) -> 0 | E11: =SUMIFS(FACILITIES!F:F,FACILITIES!$B:$B,$B11) -> 0 | F11: =SUMIFS(FACILITIES!G:G,FACILITIES!$B:$B,B11) -> 0 | G11: =SUMIFS(FACILITIES!H:H,FACILITIES!$B:$B,B11) -> 0 | H11: =SUMIFS(FACILITIES!I:I,FACILITIES!$B:$B,B11) -> 0 | I11: =SUMIFS(FACILITIES!J:J,FACILITIES!$B:$B,B11) -> 0 | J11: =SUMIFS(FACILITIES!K:K,FACILITIES!$B:$B,B11) -> 0 | K11: =SUMIFS(FACILITIES!L:L,FACILITIES!$B:$B,B11) -> 0 | L11: =SUMIFS(FACILITIES!M:M,FACILITIES!$B:$B,B11) -> 0 | M11: =SUMIFS(FACILITIES!N:N,FACILITIES!$B:$B,B11) -> 0 | N11: =SUMIFS(FACILITIES!O:O,FACILITIES!$B:$B,B11) -> 0 | O11: =SUMIFS(FACILITIES!P:P,FACILITIES!$B:$B,B11) -> 0 | P11: =SUMIFS(FACILITIES!Q:Q,FACILITIES!$B:$B,B11) -> 0 | Q11: =SUMIFS(FACILITIES!R:R,FACILITIES!$B:$B,B11) -> 0 | R11: =SUMIFS(FACILITIES!T:T,FACILITIES!B:B,B11) -> 0 | S11: =SUMIFS(FACILITIES!S:S,FACILITIES!B:B,B11) -> 0 | T11: =SUMIFS('F & B'!G:G,'F & B'!B:B,B11) -> 0 | U11: =T11*0.15 -> 0 | V11: =SUMIFS('FIXED AMOUNT'!G:G,'FIXED AMOUNT'!B:B,B11) -> 7000 | W11: =SUM(D11:V11) -> 7000 | X11: =SUMIFS('FIXED AMOUNT'!E:E,'FIXED AMOUNT'!B:B,'data base '!B:B) -> 0 | Y11: =SUMIFS('FIXED AMOUNT'!F:F,'FIXED AMOUNT'!B:B,'data base '!B:B) -> 0 | Z11: =SUMIFS('FIXED AMOUNT'!V:V,'FIXED AMOUNT'!B:B,B:B) -> 0 | AA11: =W11+X11-Y11+Z11 -> 7000 | AB11: =W11*0.1 -> 700 | AC11: 45945 | AD11: =AA11+AB11 -> 7700
A12: 11 | B12: HCFM-0512 | C12: MR.ZEESHAN IQBAL | D12: =SUMIFS(FACILITIES!E:E,FACILITIES!$B:$B,B12) -> 0 | E12: =SUMIFS(FACILITIES!F:F,FACILITIES!$B:$B,$B12) -> 6150 | F12: =SUMIFS(FACILITIES!G:G,FACILITIES!$B:$B,B12) -> 0 | G12: =SUMIFS(FACILITIES!H:H,FACILITIES!$B:$B,B12) -> 0 | H12: =SUMIFS(FACILITIES!I:I,FACILITIES!$B:$B,B12) -> 0 | I12: =SUMIFS(FACILITIES!J:J,FACILITIES!$B:$B,B12) -> 3100 | J12: =SUMIFS(FACILITIES!K:K,FACILITIES!$B:$B,B12) -> 0 | K12: =SUMIFS(FACILITIES!L:L,FACILITIES!$B:$B,B12) -> 0 | L12: =SUMIFS(FACILITIES!M:M,FACILITIES!$B:$B,B12) -> 0 | M12: =SUMIFS(FACILITIES!N:N,FACILITIES!$B:$B,B12) -> 0 | N12: =SUMIFS(FACILITIES!O:O,FACILITIES!$B:$B,B12) -> 0 | O12: =SUMIFS(FACILITIES!P:P,FACILITIES!$B:$B,B12) -> 0 | P12: =SUMIFS(FACILITIES!Q:Q,FACILITIES!$B:$B,B12) -> 0 | Q12: =SUMIFS(FACILITIES!R:R,FACILITIES!$B:$B,B12) -> 0 | R12: =SUMIFS(FACILITIES!T:T,FACILITIES!B:B,B12) -> 4000 | S12: =SUMIFS(FACILITIES!S:S,FACILITIES!B:B,B12) -> 0 | T12: =SUMIFS('F & B'!G:G,'F & B'!B:B,B12) -> 6150 | U12: =T12*0.15 -> 922.5 | V12: =SUMIFS('FIXED AMOUNT'!G:G,'FIXED AMOUNT'!B:B,B12) -> 7000 | W12: =SUM(D12:V12) -> 27322.5 | X12: =SUMIFS('FIXED AMOUNT'!E:E,'FIXED AMOUNT'!B:B,'data base '!B:B) -> 0 | Y12: =SUMIFS('FIXED AMOUNT'!F:F,'FIXED AMOUNT'!B:B,'data base '!B:B) -> 0 | Z12: =SUMIFS('FIXED AMOUNT'!V:V,'FIXED AMOUNT'!B:B,B:B) -> 3176 | AA12: =W12+X12-Y12+Z12 -> 30498.5 | AB12: =W12*0.1 -> 2732.25 | AC12: 45945 | AD12: =AA12+AB12 -> 33230.75
A13: 12 | B13: HCFM-0513 | C13: MR.SAJJAD ALI | D13: =SUMIFS(FACILITIES!E:E,FACILITIES!$B:$B,B13) -> 0 | E13: =SUMIFS(FACILITIES!F:F,FACILITIES!$B:$B,$B13) -> 0 | F13: =SUMIFS(FACILITIES!G:G,FACILITIES!$B:$B,B13) -> 0 | G13: =SUMIFS(FACILITIES!H:H,FACILITIES!$B:$B,B13) -> 0 | H13: =SUMIFS(FACILITIES!I:I,FACILITIES!$B:$B,B13) -> 0 | I13: =SUMIFS(FACILITIES!J:J,FACILITIES!$B:$B,B13) -> 0 | J13: =SUMIFS(FACILITIES!K:K,FACILITIES!$B:$B,B13) -> 0 | K13: =SUMIFS(FACILITIES!L:L,FACILITIES!$B:$B,B13) -> 0 | L13: =SUMIFS(FACILITIES!M:M,FACILITIES!$B:$B,B13) -> 0 | M13: =SUMIFS(FACILITIES!N:N,FACILITIES!$B:$B,B13) -> 0 | N13: =SUMIFS(FACILITIES!O:O,FACILITIES!$B:$B,B13) -> 0 | O13: =SUMIFS(FACILITIES!P:P,FACILITIES!$B:$B,B13) -> 12000 | P13: =SUMIFS(FACILITIES!Q:Q,FACILITIES!$B:$B,B13) -> 0 | Q13: =SUMIFS(FACILITIES!R:R,FACILITIES!$B:$B,B13) -> 0 | R13: =SUMIFS(FACILITIES!T:T,FACILITIES!B:B,B13) -> 0 | S13: =SUMIFS(FACILITIES!S:S,FACILITIES!B:B,B13) -> 0 | T13: =SUMIFS('F & B'!G:G,'F & B'!B:B,B13) -> 23647 | U13: =T13*0.15 -> 3547.05 | V13: =SUMIFS('FIXED AMOUNT'!G:G,'FIXED AMOUNT'!B:B,B13) -> 7000 | W13: =SUM(D13:V13) -> 46194.05 | X13: =SUMIFS('FIXED AMOUNT'!E:E,'FIXED AMOUNT'!B:B,'data base '!B:B) -> 0 | Y13: =SUMIFS('FIXED AMOUNT'!F:F,'FIXED AMOUNT'!B:B,'data base '!B:B) -> 0 | Z13: =SUMIFS('FIXED AMOUNT'!V:V,'FIXED AMOUNT'!B:B,B:B) -> 0 | AA13: =W13+X13-Y13+Z13 -> 46194.05 | AB13: =W13*0.1 -> 4619.405 | AC13: 45945 | AD13: =AA13+AB13 -> 50813.455
A14: 13 | B14: HCFM-0514 | C14: MR.DILEEP KUMAR | D14: =SUMIFS(FACILITIES!E:E,FACILITIES!$B:$B,B14) -> 0 | E14: =SUMIFS(FACILITIES!F:F,FACILITIES!$B:$B,$B14) -> 0 | F14: =SUMIFS(FACILITIES!G:G,FACILITIES!$B:$B,B14) -> 0 | G14: =SUMIFS(FACILITIES!H:H,FACILITIES!$B:$B,B14) -> 0 | H14: =SUMIFS(FACILITIES!I:I,FACILITIES!$B:$B,B14) -> 0 | I14: =SUMIFS(FACILITIES!J:J,FACILITIES!$B:$B,B14) -> 0 | J14: =SUMIFS(FACILITIES!K:K,FACILITIES!$B:$B,B14) -> 0 | K14: =SUMIFS(FACILITIES!L:L,FACILITIES!$B:$B,B14) -> 0 | L14: =SUMIFS(FACILITIES!M:M,FACILITIES!$B:$B,B14) -> 0 | M14: =SUMIFS(FACILITIES!N:N,FACILITIES!$B:$B,B14) -> 0 | N14: =SUMIFS(FACILITIES!O:O,FACILITIES!$B:$B,B14) -> 0 | O14: =SUMIFS(FACILITIES!P:P,FACILITIES!$B:$B,B14) -> 0 | P14: =SUMIFS(FACILITIES!Q:Q,FACILITIES!$B:$B,B14) -> 0 | Q14: =SUMIFS(FACILITIES!R:R,FACILITIES!$B:$B,B14) -> 0 | R14: =SUMIFS(FACILITIES!T:T,FACILITIES!B:B,B14) -> 0 | S14: =SUMIFS(FACILITIES!S:S,FACILITIES!B:B,B14) -> 0 | T14: =SUMIFS('F & B'!G:G,'F & B'!B:B,B14) -> 39050 | U14: =T14*0.15 -> 5857.5 | V14: =SUMIFS('FIXED AMOUNT'!G:G,'FIXED AMOUNT'!B:B,B14) -> 7000 | W14: =SUM(D14:V14) -> 51907.5 | X14: =SUMIFS('FIXED AMOUNT'!E:E,'FIXED AMOUNT'!B:B,'data base '!B:B) -> 0 | Y14: =SUMIFS('FIXED AMOUNT'!F:F,'FIXED AMOUNT'!B:B,'data base '!B:B) -> 0 | Z14: =SUMIFS('FIXED AMOUNT'!V:V,'FIXED AMOUNT'!B:B,B:B) -> 12030 | AA14: =W14+X14-Y14+Z14 -> 63937.5 | AB14: =W14*0.1 -> 5190.75 | AC14: 45945 | AD14: =AA14+AB14 -> 69128.25
A15: 14 | B15: HCFM-0515 | C15: MR.TARIQUE ZUBAIR | D15: =SUMIFS(FACILITIES!E:E,FACILITIES!$B:$B,B15) -> 0 | E15: =SUMIFS(FACILITIES!F:F,FACILITIES!$B:$B,$B15) -> 1050 | F15: =SUMIFS(FACILITIES!G:G,FACILITIES!$B:$B,B15) -> 0 | G15: =SUMIFS(FACILITIES!H:H,FACILITIES!$B:$B,B15) -> 0 | H15: =SUMIFS(FACILITIES!I:I,FACILITIES!$B:$B,B15) -> 0 | I15: =SUMIFS(FACILITIES!J:J,FACILITIES!$B:$B,B15) -> 1500 | J15: =SUMIFS(FACILITIES!K:K,FACILITIES!$B:$B,B15) -> 0 | K15: =SUMIFS(FACILITIES!L:L,FACILITIES!$B:$B,B15) -> 0 | L15: =SUMIFS(FACILITIES!M:M,FACILITIES!$B:$B,B15) -> 0 | M15: =SUMIFS(FACILITIES!N:N,FACILITIES!$B:$B,B15) -> 0 | N15: =SUMIFS(FACILITIES!O:O,FACILITIES!$B:$B,B15) -> 0 | O15: =SUMIFS(FACILITIES!P:P,FACILITIES!$B:$B,B15) -> 0 | P15: =SUMIFS(FACILITIES!Q:Q,FACILITIES!$B:$B,B15) -> 0 | Q15: =SUMIFS(FACILITIES!R:R,FACILITIES!$B:$B,B15) -> 0 | R15: =SUMIFS(FACILITIES!T:T,FACILITIES!B:B,B15) -> 0 | S15: =SUMIFS(FACILITIES!S:S,FACILITIES!B:B,B15) -> 0 | T15: =SUMIFS('F & B'!G:G,'F & B'!B:B,B15) -> 25360 | U15: =T15*0.15 -> 3804 | V15: =SUMIFS('FIXED AMOUNT'!G:G,'FIXED AMOUNT'!B:B,B15) -> 7000 | W15: =SUM(D15:V15) -> 38714 | X15: =SUMIFS('FIXED AMOUNT'!E:E,'FIXED AMOUNT'!B:B,'data base '!B:B) -> 0 | Y15: =SUMIFS('FIXED AMOUNT'!F:F,'FIXED AMOUNT'!B:B,'data base '!B:B) -> 0 | Z15: =SUMIFS('FIXED AMOUNT'!V:V,'FIXED AMOUNT'!B:B,B:B) -> 0 | AA15: =W15+X15-Y15+Z15 -> 38714 | AB15: =W15*0.1 -> 3871.4 | AC15: 45945 | AD15: 0
A16: 15 | B16: HCFM-0516 | C16: MR.ATIF SHAFQAT | D16: =SUMIFS(FACILITIES!E:E,FACILITIES!$B:$B,B16) -> 0 | E16: =SUMIFS(FACILITIES!F:F,FACILITIES!$B:$B,$B16) -> 0 | F16: =SUMIFS(FACILITIES!G:G,FACILITIES!$B:$B,B16) -> 0 | G16: =SUMIFS(FACILITIES!H:H,FACILITIES!$B:$B,B16) -> 0 | H16: =SUMIFS(FACILITIES!I:I,FACILITIES!$B:$B,B16) -> 0 | I16: =SUMIFS(FACILITIES!J:J,FACILITIES!$B:$B,B16) -> 600 | J16: =SUMIFS(FACILITIES!K:K,FACILITIES!$B:$B,B16) -> 0 | K16: =SUMIFS(FACILITIES!L:L,FACILITIES!$B:$B,B16) -> 0 | L16: =SUMIFS(FACILITIES!M:M,FACILITIES!$B:$B,B16) -> 0 | M16: =SUMIFS(FACILITIES!N:N,FACILITIES!$B:$B,B16) -> 0 | N16: =SUMIFS(FACILITIES!O:O,FACILITIES!$B:$B,B16) -> 0 | O16: =SUMIFS(FACILITIES!P:P,FACILITIES!$B:$B,B16) -> 0 | P16: =SUMIFS(FACILITIES!Q:Q,FACILITIES!$B:$B,B16) -> 0 | Q16: =SUMIFS(FACILITIES!R:R,FACILITIES!$B:$B,B16) -> 0 | R16: =SUMIFS(FACILITIES!T:T,FACILITIES!B:B,B16) -> 0 | S16: =SUMIFS(FACILITIES!S:S,FACILITIES!B:B,B16) -> 0 | T16: =SUMIFS('F & B'!G:G,'F & B'!B:B,B16) -> 3970 | U16: =T16*0.15 -> 595.5 | V16: =SUMIFS('FIXED AMOUNT'!G:G,'FIXED AMOUNT'!B:B,B16) -> 7000 | W16: =SUM(D16:V16) -> 12165.5 | X16: =SUMIFS('FIXED AMOUNT'!E:E,'FIXED AMOUNT'!B:B,'data base '!B:B) -> 0 | Y16: =SUMIFS('FIXED AMOUNT'!F:F,'FIXED AMOUNT'!B:B,'data base '!B:B) -> 0 | Z16: =SUMIFS('FIXED AMOUNT'!V:V,'FIXED AMOUNT'!B:B,B:B) -> 47155 | AA16: =W16+X16-Y16+Z16 -> 59320.5 | AB16: =W16*0.1 -> 1216.55 | AC16: 45945 | AD16: =AA16+AB16 -> 60537.05
A17: 16 | B17: HCFM-0517 | C17: DR.ATHESHAM UL HAQ RANA | D17: =SUMIFS(FACILITIES!E:E,FACILITIES!$B:$B,B17) -> 0 | E17: =SUMIFS(FACILITIES!F:F,FACILITIES!$B:$B,$B17) -> 0 | F17: =SUMIFS(FACILITIES!G:G,FACILITIES!$B:$B,B17) -> 0 | G17: =SUMIFS(FACILITIES!H:H,FACILITIES!$B:$B,B17) -> 0 | H17: =SUMIFS(FACILITIES!I:I,FACILITIES!$B:$B,B17) -> 0 | I17: =SUMIFS(FACILITIES!J:J,FACILITIES!$B:$B,B17) -> 0 | J17: =SUMIFS(FACILITIES!K:K,FACILITIES!$B:$B,B17) -> 0 | K17: =SUMIFS(FACILITIES!L:L,FACILITIES!$B:$B,B17) -> 0 | L17: =SUMIFS(FACILITIES!M:M,FACILITIES!$B:$B,B17) -> 0 | M17: =SUMIFS(FACILITIES!N:N,FACILITIES!$B:$B,B17) -> 0 | N17: =SUMIFS(FACILITIES!O:O,FACILITIES!$B:$B,B17) -> 0 | O17: =SUMIFS(FACILITIES!P:P,FACILITIES!$B:$B,B17) -> 0 | P17: =SUMIFS(FACILITIES!Q:Q,FACILITIES!$B:$B,B17) -> 0 | Q17: =SUMIFS(FACILITIES!R:R,FACILITIES!$B:$B,B17) -> 0 | R17: =SUMIFS(FACILITIES!T:T,FACILITIES!B:B,B17) -> 0 | S17: =SUMIFS(FACILITIES!S:S,FACILITIES!B:B,B17) -> 0 | T17: =SUMIFS('F & B'!G:G,'F & B'!B:B,B17) -> 0 | U17: =T17*0.15 -> 0 | V17: =SUMIFS('FIXED AMOUNT'!G:G,'FIXED AMOUNT'!B:B,B17) -> 7000 | W17: =SUM(D17:V17) -> 7000 | X17: =SUMIFS('FIXED AMOUNT'!E:E,'FIXED AMOUNT'!B:B,'data base '!B:B) -> 0 | Y17: =SUMIFS('FIXED AMOUNT'!F:F,'FIXED AMOUNT'!B:B,'data base '!B:B) -> 0 | Z17: =SUMIFS('FIXED AMOUNT'!V:V,'FIXED AMOUNT'!B:B,B:B) -> 37300 | AA17: =W17+X17-Y17+Z17 -> 44300 | AB17: =W17*0.1 -> 700 | AC17: 45945 | AD17: =AA17+AB17 -> 45000
A18: 17 | B18: HCFM-0518 | C18: DR.SANTOSH KUMAR | D18: =SUMIFS(FACILITIES!E:E,FACILITIES!$B:$B,B18) -> 0 | E18: =SUMIFS(FACILITIES!F:F,FACILITIES!$B:$B,$B18) -> 1200 | F18: =SUMIFS(FACILITIES!G:G,FACILITIES!$B:$B,B18) -> 0 | G18: =SUMIFS(FACILITIES!H:H,FACILITIES!$B:$B,B18) -> 0 | H18: =SUMIFS(FACILITIES!I:I,FACILITIES!$B:$B,B18) -> 0 | I18: =SUMIFS(FACILITIES!J:J,FACILITIES!$B:$B,B18) -> 0 | J18: =SUMIFS(FACILITIES!K:K,FACILITIES!$B:$B,B18) -> 0 | K18: =SUMIFS(FACILITIES!L:L,FACILITIES!$B:$B,B18) -> 0 | L18: =SUMIFS(FACILITIES!M:M,FACILITIES!$B:$B,B18) -> 0 | M18: =SUMIFS(FACILITIES!N:N,FACILITIES!$B:$B,B18) -> 0 | N18: =SUMIFS(FACILITIES!O:O,FACILITIES!$B:$B,B18) -> 0 | O18: =SUMIFS(FACILITIES!P:P,FACILITIES!$B:$B,B18) -> 0 | P18: =SUMIFS(FACILITIES!Q:Q,FACILITIES!$B:$B,B18) -> 0 | Q18: =SUMIFS(FACILITIES!R:R,FACILITIES!$B:$B,B18) -> 0 | R18: =SUMIFS(FACILITIES!T:T,FACILITIES!B:B,B18) -> 0 | S18: =SUMIFS(FACILITIES!S:S,FACILITIES!B:B,B18) -> 0 | T18: =SUMIFS('F & B'!G:G,'F & B'!B:B,B18) -> 0 | U18: =T18*0.15 -> 0 | V18: =SUMIFS('FIXED AMOUNT'!G:G,'FIXED AMOUNT'!B:B,B18) -> 7000 | W18: =SUM(D18:V18) -> 8200 | X18: =SUMIFS('FIXED AMOUNT'!E:E,'FIXED AMOUNT'!B:B,'data base '!B:B) -> 0 | Y18: =SUMIFS('FIXED AMOUNT'!F:F,'FIXED AMOUNT'!B:B,'data base '!B:B) -> 0 | Z18: =SUMIFS('FIXED AMOUNT'!V:V,'FIXED AMOUNT'!B:B,B:B) -> 1076 | AA18: =W18+X18-Y18+Z18 -> 9276 | AB18: =W18*0.1 -> 820 | AC18: 45945 | AD18: =AA18+AB18 -> 10096
A19: 18 | B19: HCFM-0519 | C19: DR.NAZEER HUSSAIN KALHORO | D19: =SUMIFS(FACILITIES!E:E,FACILITIES!$B:$B,B19) -> 0 | E19: =SUMIFS(FACILITIES!F:F,FACILITIES!$B:$B,$B19) -> 0 | F19: =SUMIFS(FACILITIES!G:G,FACILITIES!$B:$B,B19) -> 0 | G19: =SUMIFS(FACILITIES!H:H,FACILITIES!$B:$B,B19) -> 0 | H19: =SUMIFS(FACILITIES!I:I,FACILITIES!$B:$B,B19) -> 0 | I19: =SUMIFS(FACILITIES!J:J,FACILITIES!$B:$B,B19) -> 4000 | J19: =SUMIFS(FACILITIES!K:K,FACILITIES!$B:$B,B19) -> 0 | K19: =SUMIFS(FACILITIES!L:L,FACILITIES!$B:$B,B19) -> 0 | L19: =SUMIFS(FACILITIES!M:M,FACILITIES!$B:$B,B19) -> 0 | M19: =SUMIFS(FACILITIES!N:N,FACILITIES!$B:$B,B19) -> 0 | N19: =SUMIFS(FACILITIES!O:O,FACILITIES!$B:$B,B19) -> 0 | O19: =SUMIFS(FACILITIES!P:P,FACILITIES!$B:$B,B19) -> 0 | P19: =SUMIFS(FACILITIES!Q:Q,FACILITIES!$B:$B,B19) -> 0 | Q19: =SUMIFS(FACILITIES!R:R,FACILITIES!$B:$B,B19) -> 0 | R19: =SUMIFS(FACILITIES!T:T,FACILITIES!B:B,B19) -> 4500 | S19: =SUMIFS(FACILITIES!S:S,FACILITIES!B:B,B19) -> 0 | T19: =SUMIFS('F & B'!G:G,'F & B'!B:B,B19) -> 34425 | U19: =T19*0.15 -> 5163.75 | V19: =SUMIFS('FIXED AMOUNT'!G:G,'FIXED AMOUNT'!B:B,B19) -> 7000 | W19: =SUM(D19:V19) -> 55088.75 | X19: =SUMIFS('FIXED AMOUNT'!E:E,'FIXED AMOUNT'!B:B,'data base '!B:B) -> 0 | Y19: =SUMIFS('FIXED AMOUNT'!F:F,'FIXED AMOUNT'!B:B,'data base '!B:B) -> 0 | Z19: =SUMIFS('FIXED AMOUNT'!V:V,'FIXED AMOUNT'!B:B,B:B) -> 0 | AA19: =W19+X19-Y19+Z19 -> 55088.75 | AB19: =W19*0.1 -> 5508.875 | AC19: 45945 | AD19: =AA19+AB19 -> 60597.625
A20: 19 | B20: HCFM-0520 | C20: MR.NIZAM UDDIN NIZAMANI | D20: =SUMIFS(FACILITIES!E:E,FACILITIES!$B:$B,B20) -> 0 | E20: =SUMIFS(FACILITIES!F:F,FACILITIES!$B:$B,$B20) -> 0 | F20: =SUMIFS(FACILITIES!G:G,FACILITIES!$B:$B,B20) -> 0 | G20: =SUMIFS(FACILITIES!H:H,FACILITIES!$B:$B,B20) -> 0 | H20: =SUMIFS(FACILITIES!I:I,FACILITIES!$B:$B,B20) -> 0 | I20: =SUMIFS(FACILITIES!J:J,FACILITIES!$B:$B,B20) -> 0 | J20: =SUMIFS(FACILITIES!K:K,FACILITIES!$B:$B,B20) -> 0 | K20: =SUMIFS(FACILITIES!L:L,FACILITIES!$B:$B,B20) -> 0 | L20: =SUMIFS(FACILITIES!M:M,FACILITIES!$B:$B,B20) -> 0 | M20: =SUMIFS(FACILITIES!N:N,FACILITIES!$B:$B,B20) -> 0 | N20: =SUMIFS(FACILITIES!O:O,FACILITIES!$B:$B,B20) -> 0 | O20: =SUMIFS(FACILITIES!P:P,FACILITIES!$B:$B,B20) -> 0 | P20: =SUMIFS(FACILITIES!Q:Q,FACILITIES!$B:$B,B20) -> 0 | Q20: =SUMIFS(FACILITIES!R:R,FACILITIES!$B:$B,B20) -> 0 | R20: =SUMIFS(FACILITIES!T:T,FACILITIES!B:B,B20) -> 0 | S20: =SUMIFS(FACILITIES!S:S,FACILITIES!B:B,B20) -> 0 | T20: =SUMIFS('F & B'!G:G,'F & B'!B:B,B20) -> 98060 | U20: =T20*0.15 -> 14709 | V20: =SUMIFS('FIXED AMOUNT'!G:G,'FIXED AMOUNT'!B:B,B20) -> 7000 | W20: =SUM(D20:V20) -> 119769 | X20: =SUMIFS('FIXED AMOUNT'!E:E,'FIXED AMOUNT'!B:B,'data base '!B:B) -> 0 | Y20: =SUMIFS('FIXED AMOUNT'!F:F,'FIXED AMOUNT'!B:B,'data base '!B:B) -> 0 | Z20: =SUMIFS('FIXED AMOUNT'!V:V,'FIXED AMOUNT'!B:B,B:B) -> 0 | AA20: =W20+X20-Y20+Z20 -> 119769 | AB20: =W20*0.1 -> 11976.9 | AC20: 45945 | AD20: =AA20+AB20 -> 131745.9
A21: 20 | B21: HCFM-0521 | C21: MR.HAFEEZ AHMED SIYAL | D21: =SUMIFS(FACILITIES!E:E,FACILITIES!$B:$B,B21) -> 0 | E21: =SUMIFS(FACILITIES!F:F,FACILITIES!$B:$B,$B21) -> 1200 | F21: =SUMIFS(FACILITIES!G:G,FACILITIES!$B:$B,B21) -> 0 | G21: =SUMIFS(FACILITIES!H:H,FACILITIES!$B:$B,B21) -> 0 | H21: =SUMIFS(FACILITIES!I:I,FACILITIES!$B:$B,B21) -> 0 | I21: =SUMIFS(FACILITIES!J:J,FACILITIES!$B:$B,B21) -> 2800 | J21: =SUMIFS(FACILITIES!K:K,FACILITIES!$B:$B,B21) -> 0 | K21: =SUMIFS(FACILITIES!L:L,FACILITIES!$B:$B,B21) -> 0 | L21: =SUMIFS(FACILITIES!M:M,FACILITIES!$B:$B,B21) -> 0 | M21: =SUMIFS(FACILITIES!N:N,FACILITIES!$B:$B,B21) -> 0 | N21: =SUMIFS(FACILITIES!O:O,FACILITIES!$B:$B,B21) -> 0 | O21: =SUMIFS(FACILITIES!P:P,FACILITIES!$B:$B,B21) -> 0 | P21: =SUMIFS(FACILITIES!Q:Q,FACILITIES!$B:$B,B21) -> 0 | Q21: =SUMIFS(FACILITIES!R:R,FACILITIES!$B:$B,B21) -> 0 | R21: =SUMIFS(FACILITIES!T:T,FACILITIES!B:B,B21) -> 4000 | S21: =SUMIFS(FACILITIES!S:S,FACILITIES!B:B,B21) -> 0 | T21: =SUMIFS('F & B'!G:G,'F & B'!B:B,B21) -> 11185 | U21: =T21*0.15 -> 1677.75 | V21: =SUMIFS('FIXED AMOUNT'!G:G,'FIXED AMOUNT'!B:B,B21) -> 7000 | W21: =SUM(D21:V21) -> 27862.75 | X21: =SUMIFS('FIXED AMOUNT'!E:E,'FIXED AMOUNT'!B:B,'data base '!B:B) -> 0 | Y21: =SUMIFS('FIXED AMOUNT'!F:F,'FIXED AMOUNT'!B:B,'data base '!B:B) -> 0 | Z21: =SUMIFS('FIXED AMOUNT'!V:V,'FIXED AMOUNT'!B:B,B:B) -> 0 | AA21: =W21+X21-Y21+Z21 -> 27862.75 | AB21: =W21*0.1 -> 2786.275 | AC21: 45945 | AD21: =AA21+AB21 -> 30649.025
A22: 21 | B22: HCFM-0522 | C22: MR.IQBAL AHMED MALLAH | D22: =SUMIFS(FACILITIES!E:E,FACILITIES!$B:$B,B22) -> 0 | E22: =SUMIFS(FACILITIES!F:F,FACILITIES!$B:$B,$B22) -> 0 | F22: =SUMIFS(FACILITIES!G:G,FACILITIES!$B:$B,B22) -> 0 | G22: =SUMIFS(FACILITIES!H:H,FACILITIES!$B:$B,B22) -> 0 | H22: =SUMIFS(FACILITIES!I:I,FACILITIES!$B:$B,B22) -> 0 | I22: =SUMIFS(FACILITIES!J:J,FACILITIES!$B:$B,B22) -> 3200 | J22: =SUMIFS(FACILITIES!K:K,FACILITIES!$B:$B,B22) -> 0 | K22: =SUMIFS(FACILITIES!L:L,FACILITIES!$B:$B,B22) -> 0 | L22: =SUMIFS(FACILITIES!M:M,FACILITIES!$B:$B,B22) -> 0 | M22: =SUMIFS(FACILITIES!N:N,FACILITIES!$B:$B,B22) -> 0 | N22: =SUMIFS(FACILITIES!O:O,FACILITIES!$B:$B,B22) -> 0 | O22: =SUMIFS(FACILITIES!P:P,FACILITIES!$B:$B,B22) -> 0 | P22: =SUMIFS(FACILITIES!Q:Q,FACILITIES!$B:$B,B22) -> 0 | Q22: =SUMIFS(FACILITIES!R:R,FACILITIES!$B:$B,B22) -> 0 | R22: =SUMIFS(FACILITIES!T:T,FACILITIES!B:B,B22) -> 0 | S22: =SUMIFS(FACILITIES!S:S,FACILITIES!B:B,B22) -> 0 | T22: =SUMIFS('F & B'!G:G,'F & B'!B:B,B22) -> 22474 | U22: =T22*0.15 -> 3371.1 | V22: =SUMIFS('FIXED AMOUNT'!G:G,'FIXED AMOUNT'!B:B,B22) -> 7000 | W22: =SUM(D22:V22) -> 36045.1 | X22: =SUMIFS('FIXED AMOUNT'!E:E,'FIXED AMOUNT'!B:B,'data base '!B:B) -> 0 | Y22: =SUMIFS('FIXED AMOUNT'!F:F,'FIXED AMOUNT'!B:B,'data base '!B:B) -> 0 | Z22: =SUMIFS('FIXED AMOUNT'!V:V,'FIXED AMOUNT'!B:B,B:B) -> 0 | AA22: =W22+X22-Y22+Z22 -> 36045.1 | AB22: =W22*0.1 -> 3604.51 | AC22: 45945 | AD22: =AA22+AB22 -> 39649.61
A23: 22 | B23: HCFM-0523 | C23: MR.KANYO LAL | D23: =SUMIFS(FACILITIES!E:E,FACILITIES!$B:$B,B23) -> 0 | E23: =SUMIFS(FACILITIES!F:F,FACILITIES!$B:$B,$B23) -> 0 | F23: =SUMIFS(FACILITIES!G:G,FACILITIES!$B:$B,B23) -> 0 | G23: =SUMIFS(FACILITIES!H:H,FACILITIES!$B:$B,B23) -> 0 | H23: =SUMIFS(FACILITIES!I:I,FACILITIES!$B:$B,B23) -> 0 | I23: =SUMIFS(FACILITIES!J:J,FACILITIES!$B:$B,B23) -> 0 | J23: =SUMIFS(FACILITIES!K:K,FACILITIES!$B:$B,B23) -> 0 | K23: =SUMIFS(FACILITIES!L:L,FACILITIES!$B:$B,B23) -> 0 | L23: =SUMIFS(FACILITIES!M:M,FACILITIES!$B:$B,B23) -> 0 | M23: =SUMIFS(FACILITIES!N:N,FACILITIES!$B:$B,B23) -> 0 | N23: =SUMIFS(FACILITIES!O:O,FACILITIES!$B:$B,B23) -> 0 | O23: =SUMIFS(FACILITIES!P:P,FACILITIES!$B:$B,B23) -> 0 | P23: =SUMIFS(FACILITIES!Q:Q,FACILITIES!$B:$B,B23) -> 0 | Q23: =SUMIFS(FACILITIES!R:R,FACILITIES!$B:$B,B23) -> 0 | R23: =SUMIFS(FACILITIES!T:T,FACILITIES!B:B,B23) -> 0 | S23: =SUMIFS(FACILITIES!S:S,FACILITIES!B:B,B23) -> 0 | T23: =SUMIFS('F & B'!G:G,'F & B'!B:B,B23) -> 6600 | U23: =T23*0.15 -> 990 | V23: =SUMIFS('FIXED AMOUNT'!G:G,'FIXED AMOUNT'!B:B,B23) -> 7000 | W23: =SUM(D23:V23) -> 14590 | X23: =SUMIFS('FIXED AMOUNT'!E:E,'FIXED AMOUNT'!B:B,'data base '!B:B) -> 0 | Y23: =SUMIFS('FIXED AMOUNT'!F:F,'FIXED AMOUNT'!B:B,'data base '!B:B) -> 0 | Z23: =SUMIFS('FIXED AMOUNT'!V:V,'FIXED AMOUNT'!B:B,B:B) -> 14290 | AA23: =W23+X23-Y23+Z23 -> 28880 | AB23: =W23*0.1 -> 1459 | AC23: 45945 | AD23: =AA23+AB23 -> 30339
A24: 23 | B24: HCFM-0524 | C24: MR.MANOJ KUMAR | D24: =SUMIFS(FACILITIES!E:E,FACILITIES!$B:$B,B24) -> 3000 | E24: =SUMIFS(FACILITIES!F:F,FACILITIES!$B:$B,$B24) -> 0 | F24: =SUMIFS(FACILITIES!G:G,FACILITIES!$B:$B,B24) -> 0 | G24: =SUMIFS(FACILITIES!H:H,FACILITIES!$B:$B,B24) -> 0 | H24: =SUMIFS(FACILITIES!I:I,FACILITIES!$B:$B,B24) -> 0 | I24: =SUMIFS(FACILITIES!J:J,FACILITIES!$B:$B,B24) -> 2900 | J24: =SUMIFS(FACILITIES!K:K,FACILITIES!$B:$B,B24) -> 0 | K24: =SUMIFS(FACILITIES!L:L,FACILITIES!$B:$B,B24) -> 0 | L24: =SUMIFS(FACILITIES!M:M,FACILITIES!$B:$B,B24) -> 0 | M24: =SUMIFS(FACILITIES!N:N,FACILITIES!$B:$B,B24) -> 0 | N24: =SUMIFS(FACILITIES!O:O,FACILITIES!$B:$B,B24) -> 0 | O24: =SUMIFS(FACILITIES!P:P,FACILITIES!$B:$B,B24) -> 0 | P24: =SUMIFS(FACILITIES!Q:Q,FACILITIES!$B:$B,B24) -> 0 | Q24: =SUMIFS(FACILITIES!R:R,FACILITIES!$B:$B,B24) -> 0 | R24: =SUMIFS(FACILITIES!T:T,FACILITIES!B:B,B24) -> 0 | S24: =SUMIFS(FACILITIES!S:S,FACILITIES!B:B,B24) -> 0 | T24: =SUMIFS('F & B'!G:G,'F & B'!B:B,B24) -> 25730 | U24: =T24*0.15 -> 3859.5 | V24: =SUMIFS('FIXED AMOUNT'!G:G,'FIXED AMOUNT'!B:B,B24) -> 7000 | W24: =SUM(D24:V24) -> 42489.5 | X24: =SUMIFS('FIXED AMOUNT'!E:E,'FIXED AMOUNT'!B:B,'data base '!B:B) -> 0 | Y24: =SUMIFS('FIXED AMOUNT'!F:F,'FIXED AMOUNT'!B:B,'data base '!B:B) -> 0 | Z24: =SUMIFS('FIXED AMOUNT'!V:V,'FIXED AMOUNT'!B:B,B:B) -> 0 | AA24: =W24+X24-Y24+Z24 -> 42489.5 | AB24: =W24*0.1 -> 4248.95 | AC24: 45945 | AD24: =AA24+AB24 -> 46738.45
A25: 24 | B25: HCFM-0525 | C25: DR.SAJJAD AHMED SOLANGI | D25: =SUMIFS(FACILITIES!E:E,FACILITIES!$B:$B,B25) -> 0 | E25: =SUMIFS(FACILITIES!F:F,FACILITIES!$B:$B,$B25) -> 0 | F25: =SUMIFS(FACILITIES!G:G,FACILITIES!$B:$B,B25) -> 0 | G25: =SUMIFS(FACILITIES!H:H,FACILITIES!$B:$B,B25) -> 0 | H25: =SUMIFS(FACILITIES!I:I,FACILITIES!$B:$B,B25) -> 0 | I25: =SUMIFS(FACILITIES!J:J,FACILITIES!$B:$B,B25) -> 0 | J25: =SUMIFS(FACILITIES!K:K,FACILITIES!$B:$B,B25) -> 0 | K25: =SUMIFS(FACILITIES!L:L,FACILITIES!$B:$B,B25) -> 0 | L25: =SUMIFS(FACILITIES!M:M,FACILITIES!$B:$B,B25) -> 0 | M25: =SUMIFS(FACILITIES!N:N,FACILITIES!$B:$B,B25) -> 0 | N25: =SUMIFS(FACILITIES!O:O,FACILITIES!$B:$B,B25) -> 0 | O25: =SUMIFS(FACILITIES!P:P,FACILITIES!$B:$B,B25) -> 0 | P25: =SUMIFS(FACILITIES!Q:Q,FACILITIES!$B:$B,B25) -> 0 | Q25: =SUMIFS(FACILITIES!R:R,FACILITIES!$B:$B,B25) -> 0 | R25: =SUMIFS(FACILITIES!T:T,FACILITIES!B:B,B25) -> 0 | S25: =SUMIFS(FACILITIES!S:S,FACILITIES!B:B,B25) -> 0 | T25: =SUMIFS('F & B'!G:G,'F & B'!B:B,B25) -> 6170 | U25: =T25*0.15 -> 925.5 | V25: =SUMIFS('FIXED AMOUNT'!G:G,'FIXED AMOUNT'!B:B,B25) -> 7000 | W25: =SUM(D25:V25) -> 14095.5 | X25: =SUMIFS('FIXED AMOUNT'!E:E,'FIXED AMOUNT'!B:B,'data base '!B:B) -> 0 | Y25: =SUMIFS('FIXED AMOUNT'!F:F,'FIXED AMOUNT'!B:B,'data base '!B:B) -> 0 | Z25: =SUMIFS('FIXED AMOUNT'!V:V,'FIXED AMOUNT'!B:B,B:B) -> 0 | AA25: =W25+X25-Y25+Z25 -> 14095.5 | AB25: =W25*0.1 -> 1409.55 | AC25: 45945 | AD25: =AA25+AB25 -> 15505.05
A26: 25 | B26: HCFM-0526 | C26: MR.MUIED AHMED DURRANI | D26: =SUMIFS(FACILITIES!E:E,FACILITIES!$B:$B,B26) -> 1800 | E26: =SUMIFS(FACILITIES!F:F,FACILITIES!$B:$B,$B26) -> 0 | F26: =SUMIFS(FACILITIES!G:G,FACILITIES!$B:$B,B26) -> 0 | G26: =SUMIFS(FACILITIES!H:H,FACILITIES!$B:$B,B26) -> 0 | H26: =SUMIFS(FACILITIES!I:I,FACILITIES!$B:$B,B26) -> 0 | I26: =SUMIFS(FACILITIES!J:J,FACILITIES!$B:$B,B26) -> 900 | J26: =SUMIFS(FACILITIES!K:K,FACILITIES!$B:$B,B26) -> 0 | K26: =SUMIFS(FACILITIES!L:L,FACILITIES!$B:$B,B26) -> 0 | L26: =SUMIFS(FACILITIES!M:M,FACILITIES!$B:$B,B26) -> 0 | M26: =SUMIFS(FACILITIES!N:N,FACILITIES!$B:$B,B26) -> 0 | N26: =SUMIFS(FACILITIES!O:O,FACILITIES!$B:$B,B26) -> 0 | O26: =SUMIFS(FACILITIES!P:P,FACILITIES!$B:$B,B26) -> 0 | P26: =SUMIFS(FACILITIES!Q:Q,FACILITIES!$B:$B,B26) -> 0 | Q26: =SUMIFS(FACILITIES!R:R,FACILITIES!$B:$B,B26) -> 0 | R26: =SUMIFS(FACILITIES!T:T,FACILITIES!B:B,B26) -> 7000 | S26: =SUMIFS(FACILITIES!S:S,FACILITIES!B:B,B26) -> 0 | T26: =SUMIFS('F & B'!G:G,'F & B'!B:B,B26) -> 2975 | U26: =T26*0.15 -> 446.25 | V26: =SUMIFS('FIXED AMOUNT'!G:G,'FIXED AMOUNT'!B:B,B26) -> 7000 | W26: =SUM(D26:V26) -> 20121.25 | X26: =SUMIFS('FIXED AMOUNT'!E:E,'FIXED AMOUNT'!B:B,'data base '!B:B) -> 0 | Y26: =SUMIFS('FIXED AMOUNT'!F:F,'FIXED AMOUNT'!B:B,'data base '!B:B) -> 0 | Z26: =SUMIFS('FIXED AMOUNT'!V:V,'FIXED AMOUNT'!B:B,B:B) -> 0 | AA26: =W26+X26-Y26+Z26 -> 20121.25 | AB26: =W26*0.1 -> 2012.125 | AC26: 45945 | AD26: =AA26+AB26 -> 22133.375
A27: 26 | B27: HCFM-0527 | C27: MR.SAEED AHMED | D27: =SUMIFS(FACILITIES!E:E,FACILITIES!$B:$B,B27) -> 0 | E27: =SUMIFS(FACILITIES!F:F,FACILITIES!$B:$B,$B27) -> 0 | F27: =SUMIFS(FACILITIES!G:G,FACILITIES!$B:$B,B27) -> 0 | G27: =SUMIFS(FACILITIES!H:H,FACILITIES!$B:$B,B27) -> 0 | H27: =SUMIFS(FACILITIES!I:I,FACILITIES!$B:$B,B27) -> 0 | I27: =SUMIFS(FACILITIES!J:J,FACILITIES!$B:$B,B27) -> 0 | J27: =SUMIFS(FACILITIES!K:K,FACILITIES!$B:$B,B27) -> 0 | K27: =SUMIFS(FACILITIES!L:L,FACILITIES!$B:$B,B27) -> 0 | L27: =SUMIFS(FACILITIES!M:M,FACILITIES!$B:$B,B27) -> 0 | M27: =SUMIFS(FACILITIES!N:N,FACILITIES!$B:$B,B27) -> 0 | N27: =SUMIFS(FACILITIES!O:O,FACILITIES!$B:$B,B27) -> 0 | O27: =SUMIFS(FACILITIES!P:P,FACILITIES!$B:$B,B27) -> 0 | P27: =SUMIFS(FACILITIES!Q:Q,FACILITIES!$B:$B,B27) -> 0 | Q27: =SUMIFS(FACILITIES!R:R,FACILITIES!$B:$B,B27) -> 0 | R27: =SUMIFS(FACILITIES!T:T,FACILITIES!B:B,B27) -> 0 | S27: =SUMIFS(FACILITIES!S:S,FACILITIES!B:B,B27) -> 0 | T27: =SUMIFS('F & B'!G:G,'F & B'!B:B,B27) -> 0 | U27: =T27*0.15 -> 0 | V27: =SUMIFS('FIXED AMOUNT'!G:G,'FIXED AMOUNT'!B:B,B27) -> 7000 | W27: =SUM(D27:V27) -> 7000 | X27: =SUMIFS('FIXED AMOUNT'!E:E,'FIXED AMOUNT'!B:B,'data base '!B:B) -> 0 | Y27: =SUMIFS('FIXED AMOUNT'!F:F,'FIXED AMOUNT'!B:B,'data base '!B:B) -> 0 | Z27: =SUMIFS('FIXED AMOUNT'!V:V,'FIXED AMOUNT'!B:B,B:B) -> 8847 | AA27: =W27+X27-Y27+Z27 -> 15847 | AB27: =W27*0.1 -> 700 | AC27: 45945 | AD27: =AA27+AB27 -> 16547
... A83: 82 | B83: HCFM-0645 | C83: MUNEER AHMED | D83: =SUMIFS(FACILITIES!E:E,FACILITIES!$B:$B,B83) -> 0 | E83: =SUMIFS(FACILITIES!F:F,FACILITIES!$B:$B,$B83) -> 0 | F83: =SUMIFS(FACILITIES!G:G,FACILITIES!$B:$B,B83) -> 0 | G83: =SUMIFS(FACILITIES!H:H,FACILITIES!$B:$B,B83) -> 0 | H83: =SUMIFS(FACILITIES!I:I,FACILITIES!$B:$B,B83) -> 0 | I83: =SUMIFS(FACILITIES!J:J,FACILITIES!$B:$B,B83) -> 0 | J83: =SUMIFS(FACILITIES!K:K,FACILITIES!$B:$B,B83) -> 0 | K83: =SUMIFS(FACILITIES!L:L,FACILITIES!$B:$B,B83) -> 0 | L83: =SUMIFS(FACILITIES!M:M,FACILITIES!$B:$B,B83) -> 0 | M83: =SUMIFS(FACILITIES!N:N,FACILITIES!$B:$B,B83) -> 0 | N83: =SUMIFS(FACILITIES!O:O,FACILITIES!$B:$B,B83) -> 0 | O83: =SUMIFS(FACILITIES!P:P,FACILITIES!$B:$B,B83) -> 0 | P83: =SUMIFS(FACILITIES!Q:Q,FACILITIES!$B:$B,B83) -> 0 | Q83: =SUMIFS(FACILITIES!R:R,FACILITIES!$B:$B,B83) -> 0 | R83: =SUMIFS(FACILITIES!T:T,FACILITIES!B:B,B83) -> 0 | S83: =SUMIFS(FACILITIES!S:S,FACILITIES!B:B,B83) -> 0 | T83: =SUMIFS('F & B'!G:G,'F & B'!B:B,B83) -> 0 | U83: =T83*0.15 -> 0 | V83: =SUMIFS('FIXED AMOUNT'!G:G,'FIXED AMOUNT'!B:B,B83) -> 7000 | W83: =SUM(D83:V83) -> 7000 | X83: =SUMIFS('FIXED AMOUNT'!E:E,'FIXED AMOUNT'!B:B,'data base '!B:B) -> 0 | Y83: =SUMIFS('FIXED AMOUNT'!F:F,'FIXED AMOUNT'!B:B,'data base '!B:B) -> 0 | Z83: =SUMIFS('FIXED AMOUNT'!V:V,'FIXED AMOUNT'!B:B,B:B) -> 0 | AA83: =W83+X83-Y83+Z83 -> 7000 | AB83: =W83*0.1 -> 700 | AC83: 45945 | AD83: =AA83+AB83 -> 7700
A84: 83 | B84: HCFM-0646 | C84: BAHRIA INTERNATIONAL HOSPITAL | D84: =SUMIFS(FACILITIES!E:E,FACILITIES!$B:$B,B84) -> 0 | E84: =SUMIFS(FACILITIES!F:F,FACILITIES!$B:$B,$B84) -> 0 | F84: =SUMIFS(FACILITIES!G:G,FACILITIES!$B:$B,B84) -> 0 | G84: =SUMIFS(FACILITIES!H:H,FACILITIES!$B:$B,B84) -> 0 | H84: =SUMIFS(FACILITIES!I:I,FACILITIES!$B:$B,B84) -> 0 | I84: =SUMIFS(FACILITIES!J:J,FACILITIES!$B:$B,B84) -> 0 | J84: =SUMIFS(FACILITIES!K:K,FACILITIES!$B:$B,B84) -> 0 | K84: =SUMIFS(FACILITIES!L:L,FACILITIES!$B:$B,B84) -> 0 | L84: =SUMIFS(FACILITIES!M:M,FACILITIES!$B:$B,B84) -> 0 | M84: =SUMIFS(FACILITIES!N:N,FACILITIES!$B:$B,B84) -> 0 | N84: =SUMIFS(FACILITIES!O:O,FACILITIES!$B:$B,B84) -> 0 | O84: =SUMIFS(FACILITIES!P:P,FACILITIES!$B:$B,B84) -> 0 | P84: =SUMIFS(FACILITIES!Q:Q,FACILITIES!$B:$B,B84) -> 0 | Q84: =SUMIFS(FACILITIES!R:R,FACILITIES!$B:$B,B84) -> 0 | R84: =SUMIFS(FACILITIES!T:T,FACILITIES!B:B,B84) -> 0 | S84: =SUMIFS(FACILITIES!S:S,FACILITIES!B:B,B84) -> 0 | T84: =SUMIFS('F & B'!G:G,'F & B'!B:B,B84) -> 94400 | V84: =SUMIFS('FIXED AMOUNT'!G:G,'FIXED AMOUNT'!B:B,B84) -> 0 | W84: =SUM(D84:V84) -> 94400 | X84: =SUMIFS('FIXED AMOUNT'!E:E,'FIXED AMOUNT'!B:B,'data base '!B:B) -> 0 | Y84: =SUMIFS('FIXED AMOUNT'!F:F,'FIXED AMOUNT'!B:B,'data base '!B:B) -> 0 | Z84: =SUMIFS('FIXED AMOUNT'!V:V,'FIXED AMOUNT'!B:B,B:B) -> 0 | AA84: =W84+X84-Y84+Z84 -> 94400 | AB84: =W84*0.1 -> 9440 | AC84: 45945 | AD84: =AA84+AB84 -> 103840
A85: 84 | B85: HCFM-0647 | C85: IMRAN AHMED | D85: =SUMIFS(FACILITIES!E:E,FACILITIES!$B:$B,B85) -> 0 | E85: =SUMIFS(FACILITIES!F:F,FACILITIES!$B:$B,$B85) -> 0 | F85: =SUMIFS(FACILITIES!G:G,FACILITIES!$B:$B,B85) -> 0 | G85: =SUMIFS(FACILITIES!H:H,FACILITIES!$B:$B,B85) -> 0 | H85: =SUMIFS(FACILITIES!I:I,FACILITIES!$B:$B,B85) -> 0 | I85: =SUMIFS(FACILITIES!J:J,FACILITIES!$B:$B,B85) -> 0 | J85: =SUMIFS(FACILITIES!K:K,FACILITIES!$B:$B,B85) -> 0 | K85: =SUMIFS(FACILITIES!L:L,FACILITIES!$B:$B,B85) -> 0 | L85: =SUMIFS(FACILITIES!M:M,FACILITIES!$B:$B,B85) -> 0 | M85: =SUMIFS(FACILITIES!N:N,FACILITIES!$B:$B,B85) -> 0 | N85: =SUMIFS(FACILITIES!O:O,FACILITIES!$B:$B,B85) -> 0 | O85: =SUMIFS(FACILITIES!P:P,FACILITIES!$B:$B,B85) -> 0 | P85: =SUMIFS(FACILITIES!Q:Q,FACILITIES!$B:$B,B85) -> 0 | Q85: =SUMIFS(FACILITIES!R:R,FACILITIES!$B:$B,B85) -> 0 | R85: =SUMIFS(FACILITIES!T:T,FACILITIES!B:B,B85) -> 0 | S85: =SUMIFS(FACILITIES!S:S,FACILITIES!B:B,B85) -> 0 | T85: =SUMIFS('F & B'!G:G,'F & B'!B:B,B85) -> 0 | U85: =T85*0.15 -> 0 | V85: =SUMIFS('FIXED AMOUNT'!G:G,'FIXED AMOUNT'!B:B,B85) -> 7000 | W85: =SUM(D85:V85) -> 7000 | X85: =SUMIFS('FIXED AMOUNT'!E:E,'FIXED AMOUNT'!B:B,'data base '!B:B) -> 0 | Y85: =SUMIFS('FIXED AMOUNT'!F:F,'FIXED AMOUNT'!B:B,'data base '!B:B) -> 0 | Z85: =SUMIFS('FIXED AMOUNT'!V:V,'FIXED AMOUNT'!B:B,B:B) -> 15225 | AA85: =W85+X85-Y85+Z85 -> 22225 | AB85: =W85*0.1 -> 700 | AC85: 45945 | AD85: =AA85+AB85 -> 22925
A86: 85 | B86: HCFM-0648 | C86: AYSM MIRZA | D86: =SUMIFS(FACILITIES!E:E,FACILITIES!$B:$B,B86) -> 0 | E86: =SUMIFS(FACILITIES!F:F,FACILITIES!$B:$B,$B86) -> 750 | F86: =SUMIFS(FACILITIES!G:G,FACILITIES!$B:$B,B86) -> 0 | G86: =SUMIFS(FACILITIES!H:H,FACILITIES!$B:$B,B86) -> 0 | H86: =SUMIFS(FACILITIES!I:I,FACILITIES!$B:$B,B86) -> 0 | I86: =SUMIFS(FACILITIES!J:J,FACILITIES!$B:$B,B86) -> 1600 | J86: =SUMIFS(FACILITIES!K:K,FACILITIES!$B:$B,B86) -> 1500 | K86: =SUMIFS(FACILITIES!L:L,FACILITIES!$B:$B,B86) -> 0 | L86: =SUMIFS(FACILITIES!M:M,FACILITIES!$B:$B,B86) -> 0 | M86: =SUMIFS(FACILITIES!N:N,FACILITIES!$B:$B,B86) -> 0 | N86: =SUMIFS(FACILITIES!O:O,FACILITIES!$B:$B,B86) -> 0 | O86: =SUMIFS(FACILITIES!P:P,FACILITIES!$B:$B,B86) -> 0 | P86: =SUMIFS(FACILITIES!Q:Q,FACILITIES!$B:$B,B86) -> 0 | Q86: =SUMIFS(FACILITIES!R:R,FACILITIES!$B:$B,B86) -> 0 | R86: =SUMIFS(FACILITIES!T:T,FACILITIES!B:B,B86) -> 0 | S86: =SUMIFS(FACILITIES!S:S,FACILITIES!B:B,B86) -> 0 | T86: =SUMIFS('F & B'!G:G,'F & B'!B:B,B86) -> 21714 | U86: =T86*0.15 -> 3257.1 | V86: =SUMIFS('FIXED AMOUNT'!G:G,'FIXED AMOUNT'!B:B,B86) -> 7000 | W86: =SUM(D86:V86) -> 35821.1 | X86: =SUMIFS('FIXED AMOUNT'!E:E,'FIXED AMOUNT'!B:B,'data base '!B:B) -> 0 | Y86: =SUMIFS('FIXED AMOUNT'!F:F,'FIXED AMOUNT'!B:B,'data base '!B:B) -> 0 | Z86: =SUMIFS('FIXED AMOUNT'!V:V,'FIXED AMOUNT'!B:B,B:B) -> 7926 | AA86: =W86+X86-Y86+Z86 -> 43747.1 | AB86: =W86*0.1 -> 3582.11 | AC86: 45945 | AD86: =AA86+AB86 -> 47329.21
A87: 86 | B87: HCFM-0649 | C87: IFTIKHAR SHAH | D87: =SUMIFS(FACILITIES!E:E,FACILITIES!$B:$B,B87) -> 0 | E87: =SUMIFS(FACILITIES!F:F,FACILITIES!$B:$B,$B87) -> 0 | F87: =SUMIFS(FACILITIES!G:G,FACILITIES!$B:$B,B87) -> 0 | G87: =SUMIFS(FACILITIES!H:H,FACILITIES!$B:$B,B87) -> 0 | H87: =SUMIFS(FACILITIES!I:I,FACILITIES!$B:$B,B87) -> 0 | I87: =SUMIFS(FACILITIES!J:J,FACILITIES!$B:$B,B87) -> 0 | J87: =SUMIFS(FACILITIES!K:K,FACILITIES!$B:$B,B87) -> 0 | K87: =SUMIFS(FACILITIES!L:L,FACILITIES!$B:$B,B87) -> 0 | L87: =SUMIFS(FACILITIES!M:M,FACILITIES!$B:$B,B87) -> 0 | M87: =SUMIFS(FACILITIES!N:N,FACILITIES!$B:$B,B87) -> 0 | N87: =SUMIFS(FACILITIES!O:O,FACILITIES!$B:$B,B87) -> 0 | O87: =SUMIFS(FACILITIES!P:P,FACILITIES!$B:$B,B87) -> 0 | P87: =SUMIFS(FACILITIES!Q:Q,FACILITIES!$B:$B,B87) -> 0 | Q87: =SUMIFS(FACILITIES!R:R,FACILITIES!$B:$B,B87) -> 0 | R87: =SUMIFS(FACILITIES!T:T,FACILITIES!B:B,B87) -> 0 | S87: =SUMIFS(FACILITIES!S:S,FACILITIES!B:B,B87) -> 0 | T87: =SUMIFS('F & B'!G:G,'F & B'!B:B,B87) -> 76200 | U87: =T87*0.15 -> 11430 | V87: =SUMIFS('FIXED AMOUNT'!G:G,'FIXED AMOUNT'!B:B,B87) -> 7000 | W87: =SUM(D87:V87) -> 94630 | X87: =SUMIFS('FIXED AMOUNT'!E:E,'FIXED AMOUNT'!B:B,'data base '!B:B) -> 0 | Y87: =SUMIFS('FIXED AMOUNT'!F:F,'FIXED AMOUNT'!B:B,'data base '!B:B) -> 0 | Z87: =SUMIFS('FIXED AMOUNT'!V:V,'FIXED AMOUNT'!B:B,B:B) -> 0 | AA87: =W87+X87-Y87+Z87 -> 94630 | AB87: =W87*0.1 -> 9463 | AC87: 45945 | AD87: =AA87+AB87 -> 104093
A88: 87 | B88: HCFM-0650 | C88: KHURRAM FIRDOUS | D88: =SUMIFS(FACILITIES!E:E,FACILITIES!$B:$B,B88) -> 0 | E88: =SUMIFS(FACILITIES!F:F,FACILITIES!$B:$B,$B88) -> 0 | F88: =SUMIFS(FACILITIES!G:G,FACILITIES!$B:$B,B88) -> 0 | G88: =SUMIFS(FACILITIES!H:H,FACILITIES!$B:$B,B88) -> 0 | H88: =SUMIFS(FACILITIES!I:I,FACILITIES!$B:$B,B88) -> 0 | I88: =SUMIFS(FACILITIES!J:J,FACILITIES!$B:$B,B88) -> 2800 | J88: =SUMIFS(FACILITIES!K:K,FACILITIES!$B:$B,B88) -> 0 | K88: =SUMIFS(FACILITIES!L:L,FACILITIES!$B:$B,B88) -> 0 | L88: =SUMIFS(FACILITIES!M:M,FACILITIES!$B:$B,B88) -> 0 | M88: =SUMIFS(FACILITIES!N:N,FACILITIES!$B:$B,B88) -> 0 | N88: =SUMIFS(FACILITIES!O:O,FACILITIES!$B:$B,B88) -> 5500 | O88: =SUMIFS(FACILITIES!P:P,FACILITIES!$B:$B,B88) -> 0 | P88: =SUMIFS(FACILITIES!Q:Q,FACILITIES!$B:$B,B88) -> 0 | Q88: =SUMIFS(FACILITIES!R:R,FACILITIES!$B:$B,B88) -> 0 | R88: =SUMIFS(FACILITIES!T:T,FACILITIES!B:B,B88) -> 0 | S88: =SUMIFS(FACILITIES!S:S,FACILITIES!B:B,B88) -> 0 | T88: =SUMIFS('F & B'!G:G,'F & B'!B:B,B88) -> 16250 | U88: =T88*0.15 -> 2437.5 | V88: =SUMIFS('FIXED AMOUNT'!G:G,'FIXED AMOUNT'!B:B,B88) -> 7000 | W88: =SUM(D88:V88) -> 33987.5 | X88: =SUMIFS('FIXED AMOUNT'!E:E,'FIXED AMOUNT'!B:B,'data base '!B:B) -> 0 | Y88: =SUMIFS('FIXED AMOUNT'!F:F,'FIXED AMOUNT'!B:B,'data base '!B:B) -> 0 | Z88: =SUMIFS('FIXED AMOUNT'!V:V,'FIXED AMOUNT'!B:B,B:B) -> 2085 | AA88: =W88+X88-Y88+Z88 -> 36072.5 | AB88: =W88*0.1 -> 3398.75 | AC88: 45945 | AD88: =AA88+AB88 -> 39471.25
A89: 88 | B89: HCFM-0651 | C89: ALI LEGHARI | D89: =SUMIFS(FACILITIES!E:E,FACILITIES!$B:$B,B89) -> 0 | E89: =SUMIFS(FACILITIES!F:F,FACILITIES!$B:$B,$B89) -> 0 | F89: =SUMIFS(FACILITIES!G:G,FACILITIES!$B:$B,B89) -> 0 | G89: =SUMIFS(FACILITIES!H:H,FACILITIES!$B:$B,B89) -> 0 | H89: =SUMIFS(FACILITIES!I:I,FACILITIES!$B:$B,B89) -> 0 | I89: =SUMIFS(FACILITIES!J:J,FACILITIES!$B:$B,B89) -> 0 | J89: =SUMIFS(FACILITIES!K:K,FACILITIES!$B:$B,B89) -> 0 | K89: =SUMIFS(FACILITIES!L:L,FACILITIES!$B:$B,B89) -> 0 | L89: =SUMIFS(FACILITIES!M:M,FACILITIES!$B:$B,B89) -> 0 | M89: =SUMIFS(FACILITIES!N:N,FACILITIES!$B:$B,B89) -> 0 | N89: =SUMIFS(FACILITIES!O:O,FACILITIES!$B:$B,B89) -> 0 | O89: =SUMIFS(FACILITIES!P:P,FACILITIES!$B:$B,B89) -> 0 | P89: =SUMIFS(FACILITIES!Q:Q,FACILITIES!$B:$B,B89) -> 0 | Q89: =SUMIFS(FACILITIES!R:R,FACILITIES!$B:$B,B89) -> 0 | R89: =SUMIFS(FACILITIES!T:T,FACILITIES!B:B,B89) -> 365000 | S89: =SUMIFS(FACILITIES!S:S,FACILITIES!B:B,B89) -> 100000 | T89: =SUMIFS('F & B'!G:G,'F & B'!B:B,B89) -> 80050 | U89: =T89*0.15 -> 12007.5 | V89: =SUMIFS('FIXED AMOUNT'!G:G,'FIXED AMOUNT'!B:B,B89) -> 7000 | W89: =SUM(D89:V89) -> 564057.5 | X89: =SUMIFS('FIXED AMOUNT'!E:E,'FIXED AMOUNT'!B:B,'data base '!B:B) -> 0 | Y89: =SUMIFS('FIXED AMOUNT'!F:F,'FIXED AMOUNT'!B:B,'data base '!B:B) -> 0 | Z89: =SUMIFS('FIXED AMOUNT'!V:V,'FIXED AMOUNT'!B:B,B:B) -> 0 | AA89: =W89+X89-Y89+Z89 -> 564057.5 | AB89: =W89*0.1 -> 56405.75 | AC89: 45945 | AD89: =AA89+AB89 -> 620463.25
A90: 89 | B90: HCFM-0652 | C90: Dr. AZAD ALI | D90: =SUMIFS(FACILITIES!E:E,FACILITIES!$B:$B,B90) -> 0 | E90: =SUMIFS(FACILITIES!F:F,FACILITIES!$B:$B,$B90) -> 0 | F90: =SUMIFS(FACILITIES!G:G,FACILITIES!$B:$B,B90) -> 0 | G90: =SUMIFS(FACILITIES!H:H,FACILITIES!$B:$B,B90) -> 0 | H90: =SUMIFS(FACILITIES!I:I,FACILITIES!$B:$B,B90) -> 0 | I90: =SUMIFS(FACILITIES!J:J,FACILITIES!$B:$B,B90) -> 0 | J90: =SUMIFS(FACILITIES!K:K,FACILITIES!$B:$B,B90) -> 0 | K90: =SUMIFS(FACILITIES!L:L,FACILITIES!$B:$B,B90) -> 0 | L90: =SUMIFS(FACILITIES!M:M,FACILITIES!$B:$B,B90) -> 0 | M90: =SUMIFS(FACILITIES!N:N,FACILITIES!$B:$B,B90) -> 0 | N90: =SUMIFS(FACILITIES!O:O,FACILITIES!$B:$B,B90) -> 0 | O90: =SUMIFS(FACILITIES!P:P,FACILITIES!$B:$B,B90) -> 0 | P90: =SUMIFS(FACILITIES!Q:Q,FACILITIES!$B:$B,B90) -> 0 | Q90: =SUMIFS(FACILITIES!R:R,FACILITIES!$B:$B,B90) -> 0 | R90: =SUMIFS(FACILITIES!T:T,FACILITIES!B:B,B90) -> 0 | S90: =SUMIFS(FACILITIES!S:S,FACILITIES!B:B,B90) -> 0 | T90: =SUMIFS('F & B'!G:G,'F & B'!B:B,B90) -> 0 | U90: =T90*0.15 -> 0 | V90: =SUMIFS('FIXED AMOUNT'!G:G,'FIXED AMOUNT'!B:B,B90) -> 7000 | W90: =SUM(D90:V90) -> 7000 | X90: =SUMIFS('FIXED AMOUNT'!E:E,'FIXED AMOUNT'!B:B,'data base '!B:B) -> 0 | Y90: =SUMIFS('FIXED AMOUNT'!F:F,'FIXED AMOUNT'!B:B,'data base '!B:B) -> 0 | Z90: =SUMIFS('FIXED AMOUNT'!V:V,'FIXED AMOUNT'!B:B,B:B) -> 31471 | AA90: =W90+X90-Y90+Z90 -> 38471 | AB90: =W90*0.1 -> 700 | AC90: 45945 | AD90: =AA90+AB90 -> 39171
A91: 90 | B91: HCFM-0653 | C91: AMEER MUHAMMAD | D91: =SUMIFS(FACILITIES!E:E,FACILITIES!$B:$B,B91) -> 0 | E91: =SUMIFS(FACILITIES!F:F,FACILITIES!$B:$B,$B91) -> 0 | F91: =SUMIFS(FACILITIES!G:G,FACILITIES!$B:$B,B91) -> 0 | G91: =SUMIFS(FACILITIES!H:H,FACILITIES!$B:$B,B91) -> 0 | H91: =SUMIFS(FACILITIES!I:I,FACILITIES!$B:$B,B91) -> 0 | I91: =SUMIFS(FACILITIES!J:J,FACILITIES!$B:$B,B91) -> 0 | J91: =SUMIFS(FACILITIES!K:K,FACILITIES!$B:$B,B91) -> 0 | K91: =SUMIFS(FACILITIES!L:L,FACILITIES!$B:$B,B91) -> 0 | L91: =SUMIFS(FACILITIES!M:M,FACILITIES!$B:$B,B91) -> 0 | M91: =SUMIFS(FACILITIES!N:N,FACILITIES!$B:$B,B91) -> 0 | N91: =SUMIFS(FACILITIES!O:O,FACILITIES!$B:$B,B91) -> 0 | O91: =SUMIFS(FACILITIES!P:P,FACILITIES!$B:$B,B91) -> 0 | P91: =SUMIFS(FACILITIES!Q:Q,FACILITIES!$B:$B,B91) -> 0 | Q91: =SUMIFS(FACILITIES!R:R,FACILITIES!$B:$B,B91) -> 0 | R91: =SUMIFS(FACILITIES!T:T,FACILITIES!B:B,B91) -> 0 | S91: =SUMIFS(FACILITIES!S:S,FACILITIES!B:B,B91) -> 0 | T91: =SUMIFS('F & B'!G:G,'F & B'!B:B,B91) -> 0 | U91: =T91*0.15 -> 0 | V91: =SUMIFS('FIXED AMOUNT'!G:G,'FIXED AMOUNT'!B:B,B91) -> 7000 | W91: =SUM(D91:V91) -> 7000 | X91: =SUMIFS('FIXED AMOUNT'!E:E,'FIXED AMOUNT'!B:B,'data base '!B:B) -> 0 | Y91: =SUMIFS('FIXED AMOUNT'!F:F,'FIXED AMOUNT'!B:B,'data base '!B:B) -> 0 | Z91: =SUMIFS('FIXED AMOUNT'!V:V,'FIXED AMOUNT'!B:B,B:B) -> 0 | AA91: =W91+X91-Y91+Z91 -> 7000 | AB91: =W91*0.1 -> 700 | AC91: 45945 | AD91: =AA91+AB91 -> 7700
A92: 91 | B92: HCFM-0654 | C92: SYED JIBRAN MUSHTAQ | D92: =SUMIFS(FACILITIES!E:E,FACILITIES!$B:$B,B92) -> 1200 | E92: =SUMIFS(FACILITIES!F:F,FACILITIES!$B:$B,$B92) -> 0 | F92: =SUMIFS(FACILITIES!G:G,FACILITIES!$B:$B,B92) -> 0 | G92: =SUMIFS(FACILITIES!H:H,FACILITIES!$B:$B,B92) -> 0 | H92: =SUMIFS(FACILITIES!I:I,FACILITIES!$B:$B,B92) -> 0 | I92: =SUMIFS(FACILITIES!J:J,FACILITIES!$B:$B,B92) -> 5400 | J92: =SUMIFS(FACILITIES!K:K,FACILITIES!$B:$B,B92) -> 0 | K92: =SUMIFS(FACILITIES!L:L,FACILITIES!$B:$B,B92) -> 0 | L92: =SUMIFS(FACILITIES!M:M,FACILITIES!$B:$B,B92) -> 0 | M92: =SUMIFS(FACILITIES!N:N,FACILITIES!$B:$B,B92) -> 1500 | N92: =SUMIFS(FACILITIES!O:O,FACILITIES!$B:$B,B92) -> 0 | O92: =SUMIFS(FACILITIES!P:P,FACILITIES!$B:$B,B92) -> 11500 | P92: =SUMIFS(FACILITIES!Q:Q,FACILITIES!$B:$B,B92) -> 0 | Q92: =SUMIFS(FACILITIES!R:R,FACILITIES!$B:$B,B92) -> 0 | R92: =SUMIFS(FACILITIES!T:T,FACILITIES!B:B,B92) -> 0 | S92: =SUMIFS(FACILITIES!S:S,FACILITIES!B:B,B92) -> 0 | T92: =SUMIFS('F & B'!G:G,'F & B'!B:B,B92) -> 29370 | U92: =T92*0.15 -> 4405.5 | V92: =SUMIFS('FIXED AMOUNT'!G:G,'FIXED AMOUNT'!B:B,B92) -> 7000 | W92: =SUM(D92:V92) -> 60375.5 | X92: =SUMIFS('FIXED AMOUNT'!E:E,'FIXED AMOUNT'!B:B,'data base '!B:B) -> 0 | Y92: =SUMIFS('FIXED AMOUNT'!F:F,'FIXED AMOUNT'!B:B,'data base '!B:B) -> 0 | Z92: =SUMIFS('FIXED AMOUNT'!V:V,'FIXED AMOUNT'!B:B,B:B) -> 0 | AA92: =W92+X92-Y92+Z92 -> 60375.5 | AB92: =W92*0.1 -> 6037.55 | AC92: 45945 | AD92: =AA92+AB92 -> 66413.05
