Workbook

Sheet Member information
A1: Membership Number | B1: Name
A2: HCFM-0641 | B2: AAMIR RASOOL
A3: HCFM-AH001 | B3: ADMIRAL AHMED HAYAT
A4: HCFM-0681 | B4: ADVANTURE LAND
A5: HCFM-0651 | B5: ALI LEGHARI
A6: HCFM-0653 | B6: AMEER MUHAMMAD
A7: HCFM-0661 | B7: ARSLAN KHAN ABRO
A8: HCFM-0642 | B8: ASIF ASHFAQ
A9: HCFM-0648 | B9: AYSM MIRZA
A10: HCFM-0646 | B10: BAHRIA INTERNATIONAL HOSPITAL
A11: HCFM-0581 | B11: Brig Dr Ghulam Mehdi (Retd)
A12: HCFM-0595 | B12: BRIG.KHALID MEHMOOD
... A122: HCFM-0588 | B122: ZULFIQAR AHMED MEMON
A123: HCFM-0675

Sheet Menu Items
A1: HERITAGE CLUB BAHRIA TOWN KARACHI
A4: HERITAGE CLUB BAHRIA TOWN KARACHI
D6: Category
A7: 1 | B7: AGAVE NECTAR | C7: 550
A8: 2 | B8: AKBERI BOTI TIKKA | C8: 600 | D8: BBQ
A9: 3 | B9: ALMOND CAKE | C9: 1500 | D9: BAKERY
A10: 4 | B10: ALMOND COOKIES | C10: 400
A11: 5 | B11: ALMOND COOKIES 500GM | C11: 800
A12: 6 | B12: ALOO SAMOSA | C12: 100
A13: 7 | B13: AMBERI FISH TIKKA | C13: 1450
A14: 8 | B14: AMERICAN ALMOND BROWNE | C14: 400
A15: 9 | B15: AMERICAN CHOPSUEY | C15: 950
A16: 11 | B16: APPLE JUICE | C16: 200
A17: 12 | B17: APPLE PIE | C17: 450
A18: 13 | B18: APPLE PIE ALA MODE | C18: 300
A19: 14 | B19: APPLE PIE HOT SAUCE | C19: 275
A20: 15 | B20: APRICOT PUDDING | C20: 600
A21: 16 | B21: ASSORTED COOKIES | C21: 400
... A60: 56 | B60: BUFFET LUNCH | C60: 3000
A61: 57 | B61: BUFFET PARTY | C61: 3700 | D61: FOR ASHOK KUMAR
A62: 58 | B62: BUN | C62: 60
A63: 59 | B63: BUTTER CHICKEN | C63: 750
A64: 60 | B64: BUTTER NAAN | C64: 150
A65: 61 | B65: CAKE PLATE | C65: 200
A66: 62 | B66: CAPPUCCINO COFFEE | C66: 350
A67: 63 | B67: CHANDAN KABAB | C67: 1500
A68: 64 | B68: CHEESE CAKE | C68: 350
A69: 65 | B69: CHEESE NAAN | C69: 200
A70: 66 | B70: CHEESE PASTRY | C70: 250
A71: 67 | B71: CHICKEN BIRYANI | C71: 600
A72: 68 | B72: CHICKEN BURGER | C72: 550
A73: 69 | B73: CHICKEN CAESAR SALAD | C73: 1200
... A168: 166 | B168: FRIED PRAWN | C168: 999
B169: MINERAL WATER SMALL | C169: 100
A170: 168 | B170: FRUIT CAKE | C170: 1200
A171: 169 | B171: FRUIT CAKE 2 POUND | C171: 1800
A172: 170 | B172: FRUIT YOGURT | C172: 370
A173: 171 | B173: FUDGE BROWNE | C173: 400
A174: 172 | B174: FUDGE PASTRY | C174: 250
A175: 173 | B175: FULL CHICKEN QUICHE | C175: 1500
...

Sheet Sheet1
A3: RECEIPT | F3: RECEIPT
A7: Thank you for dining at The Heritage Club. Please review the itemized charges below. Ensure all details are correct. | F7: Thank you for dining at The Heritage Club. Please review the itemized charges below. Ensure all details are correct.
A9: Customer Information | F9: Customer Information
A11: Member ID: | B11: HCFM-0534 | F11: Member ID: | G11: =B11 -> HCFM-0534
A12: Member Name: | B12: =VLOOKUP(B11,'Member information'!A:B,2,FALSE) -> MR.PIR MUJEEB JAN SARHANDI | F12: Member Name: | G12: =B12 -> MR.PIR MUJEEB JAN SARHANDI
A13: Date: | B13: 46020 | F13: Date: | G13: =B13 -> 46020
A14: Time: | B14: 0.45978009 | F14: =A14 -> Time: | G14: =B14 -> 0.45978009
A15: Itemized Charges | F15: Itemized Charges
A17: Item | B17: Quantity | C17: Unit Price | D17: Total Price | F17: Item | G17: Quantity | H17: Unit Price | I17: Total Price
A18: BUFFET DINNER | B18: 300 | C18: 905 | D18: =IF(C18&B18="","",C18*B18) -> 271500 | F18: =IF(A18="","",A18) -> BUFFET DINNER | G18: =IF(B18="","",B18) -> 300 | H18: =IF(C18="","",C18) -> 905 | I18: =IF(D18="","",D18) -> 271500
A19: VANU CHARGES | B19: 2 | C19: 82500 | D19: =IF(C19&B19="","",C19*B19) -> 165000 | F19: =IF(A19="","",A19) -> VANU CHARGES | G19: =IF(B19="","",B19) -> 2 | H19: =IF(C19="","",C19) -> 82500 | I19: =IF(D19="","",D19) -> 165000
C20: =IFERROR(VLOOKUP(A20,'Menu Items'!B:C,2,FALSE),"") | D20: =IF(C20&B20="","",C20*B20) | F20: =IF(A20="","",A20) | G20: =IF(B20="","",B20) | H20: =IF(C20="","",C20) | I20: =IF(D20="","",D20)
C21: =IFERROR(VLOOKUP(A21,'Menu Items'!B:C,2,FALSE),"") | D21: =IF(C21&B21="","",C21*B21) | F21: =IF(A21="","",A21) | G21: =IF(B21="","",B21) | H21: =IF(C21="","",C21) | I21: =IF(D21="","",D21)
C22: =IFERROR(VLOOKUP(A22,'Menu Items'!B:C,2,FALSE),"") | D22: =IF(C22&B22="","",C22*B22) | F22: =IF(A22="","",A22) | G22: =IF(B22="","",B22) | H22: =IF(C22="","",C22) | I22: =IF(D22="","",D22)
C23: =IFERROR(VLOOKUP(A23,'Menu Items'!B:C,2,FALSE),"") | D23: =IF(C23&B23="","",C23*B23) | F23: =IF(A23="","",A23) | G23: =IF(B23="","",B23) | H23: =IF(C23="","",C23) | I23: =IF(D23="","",D23)
D24: =IF(C24&B24="","",C24*B24) | F24: =IF(A24="","",A24) | G24: =IF(B24="","",B24) | H24: =IF(C24="","",C24) | I24: =IF(D24="","",D24)
C25: =IFERROR(VLOOKUP(A25,'Menu Items'!B:C,2,FALSE),"") | D25: =IF(C25&B25="","",C25*B25) | F25: =IF(A25="","",A25) | G25: =IF(B25="","",B25) | H25: =IF(C25="","",C25) | I25: =IF(D25="","",D25)
C26: =IFERROR(VLOOKUP(A26,'Menu Items'!B:C,2,FALSE),"") | D26: =IF(C26&B26="","",C26*B26) | F26: =IF(A26="","",A26) | G26: =IF(B26="","",B26) | H26: =IF(C26="","",C26) | I26: =IF(D26="","",D26)
C27: =IFERROR(VLOOKUP(A27,'Menu Items'!B:C,2,FALSE),"") | D27: =IF(C27&B27="","",C27*B27) | F27: =IF(A27="","",A27) | G27: =IF(B27="","",B27) | H27: =IF(C27="","",C27) | I27: =IF(D27="","",D27)
C28: =IFERROR(VLOOKUP(A28,'Menu Items'!B:C,2,FALSE),"") | D28: =IF(C28&B28="","",C28*B28) | F28: =IF(A28="","",A28) | G28: =IF(B28="","",B28) | H28: =IF(C28="","",C28) | I28: =IF(D28="","",D28)
C29: =IFERROR(VLOOKUP(A29,'Menu Items'!B:C,2,FALSE),"") | D29: =IF(C29&B29="","",C29*B29) | F29: =IF(A29="","",A29) | G29: =IF(B29="","",B29) | H29: =IF(C29="","",C29) | I29: =IF(D29="","",D29)
C30: =IFERROR(VLOOKUP(A30,'Menu Items'!B:C,2,FALSE),"") | D30: =IF(C30&B30="","",C30*B30) | F30: =IF(A30="","",A30) | G30: =IF(B30="","",B30) | H30: =IF(C30="","",C30) | I30: =IF(D30="","",D30)
C31: =IFERROR(VLOOKUP(A31,'Menu Items'!B:C,2,FALSE),"") | D31: =IF(C31&B31="","",C31*B31) | F31: =IF(A31="","",A31) | G31: =IF(B31="","",B31) | H31: =IF(C31="","",C31) | I31: =IF(D31="","",D31)
A34: Subtotal: Food and Beverages = | B34: =SUM(D18:D32) -> 436500 | F34: Subtotal: Food and Beverages = | G34: =B34 -> 436500
A36: Taxes and Fees | F36: Taxes and Fees
A38: Sales Tax (15%): | B38: =B34*0.15 -> 65475 | F38: Sales Tax (15%): | G38: =B38 -> 65475
A40: Total Amount Due | F40: Total Amount Due
A42: Grand Total: | B42: =SUM(B38,B34) -> 501975 | F42: Grand Total: | G42: =SUM(G38,G34) -> 501975
C46: Member Signature: | H46: *MEMBERS COPY*
